telegram.ext.dispatcher - ERROR - No error handlers are registered, logging exception.
Traceback (most recent call last):
  File "/Library/Frameworks/Python.framework/Versions/3.7/lib/python3.7/site-packages/telegram/ext/dispatcher.py", line 372, in process_update
    handler.handle_update(update, self, check, context)
  File "/Library/Frameworks/Python.framework/Versions/3.7/lib/python3.7/site-packages/telegram/ext/handler.py", line 120, in handle_update
    return self.callback(dispatcher.bot, update, **optional_args)
  File "botephem.py", line 16, in planets
    update.message.text("Привет, То")
TypeError: 'str' object is not callable
telegram.ext.dispatcher - ERROR - No error handlers are registered, logging exception.
Traceback (most recent call last):
  File "/Library/Frameworks/Python.framework/Versions/3.7/lib/python3.7/site-packages/telegram/ext/dispatcher.py", line 372, in process_update
    handler.handle_update(update, self, check, context)
  File "/Library/Frameworks/Python.framework/Versions/3.7/lib/python3.7/site-packages/telegram/ext/handler.py", line 120, in handle_update
    return self.callback(dispatcher.bot, update, **optional_args)
  File "botephem.py", line 17, in planets
    someplanet = ephem.myplanet('2019/09/12')
AttributeError: module 'ephem' has no attribute 'myplanet'
telegram.ext.dispatcher - ERROR - No error handlers are registered, logging exception.
Traceback (most recent call last):
  File "/Library/Frameworks/Python.framework/Versions/3.7/lib/python3.7/site-packages/telegram/ext/dispatcher.py", line 372, in process_update
    handler.handle_update(update, self, check, context)
  File "/Library/Frameworks/Python.framework/Versions/3.7/lib/python3.7/site-packages/telegram/ext/handler.py", line 120, in handle_update
    return self.callback(dispatcher.bot, update, **optional_args)
  File "botephem.py", line 17, in planets
    someplanet = ephem.myplanet('2019/09/12')
AttributeError: module 'ephem' has no attribute 'myplanet'
telegram.ext.dispatcher - ERROR - No error handlers are registered, logging exception.
Traceback (most recent call last):
  File "/Library/Frameworks/Python.framework/Versions/3.7/lib/python3.7/site-packages/telegram/ext/dispatcher.py", line 372, in process_update
    handler.handle_update(update, self, check, context)
  File "/Library/Frameworks/Python.framework/Versions/3.7/lib/python3.7/site-packages/telegram/ext/handler.py", line 120, in handle_update
    return self.callback(dispatcher.bot, update, **optional_args)
  File "botephem.py", line 18, in planets
    someplanet = ephem.myplanet('2019/09/12')
AttributeError: module 'ephem' has no attribute 'myplanet'
telegram.ext.dispatcher - ERROR - No error handlers are registered, logging exception.
Traceback (most recent call last):
  File "/Library/Frameworks/Python.framework/Versions/3.7/lib/python3.7/site-packages/telegram/ext/dispatcher.py", line 372, in process_update
    handler.handle_update(update, self, check, context)
  File "/Library/Frameworks/Python.framework/Versions/3.7/lib/python3.7/site-packages/telegram/ext/handler.py", line 120, in handle_update
    return self.callback(dispatcher.bot, update, **optional_args)
  File "botephem.py", line 18, in planets
    someplanet = ephem.myplanet('2019/09/12')
AttributeError: module 'ephem' has no attribute 'myplanet'
telegram.ext.dispatcher - ERROR - No error handlers are registered, logging exception.
Traceback (most recent call last):
  File "/Library/Frameworks/Python.framework/Versions/3.7/lib/python3.7/site-packages/telegram/ext/dispatcher.py", line 372, in process_update
    handler.handle_update(update, self, check, context)
  File "/Library/Frameworks/Python.framework/Versions/3.7/lib/python3.7/site-packages/telegram/ext/handler.py", line 120, in handle_update
    return self.callback(dispatcher.bot, update, **optional_args)
  File "botephem.py", line 18, in planets
    someplanet = ephem.myplanet('2019/09/12')
AttributeError: module 'ephem' has no attribute 'myplanet'
telegram.ext.dispatcher - ERROR - No error handlers are registered, logging exception.
Traceback (most recent call last):
  File "/Library/Frameworks/Python.framework/Versions/3.7/lib/python3.7/site-packages/telegram/ext/dispatcher.py", line 372, in process_update
    handler.handle_update(update, self, check, context)
  File "/Library/Frameworks/Python.framework/Versions/3.7/lib/python3.7/site-packages/telegram/ext/handler.py", line 120, in handle_update
    return self.callback(dispatcher.bot, update, **optional_args)
  File "botephem.py", line 18, in planets
    someplanet = ephem.myplanet('2019/09/12')
AttributeError: module 'ephem' has no attribute 'myplanet'
telegram.ext.dispatcher - ERROR - No error handlers are registered, logging exception.
Traceback (most recent call last):
  File "/Library/Frameworks/Python.framework/Versions/3.7/lib/python3.7/site-packages/telegram/ext/dispatcher.py", line 372, in process_update
    handler.handle_update(update, self, check, context)
  File "/Library/Frameworks/Python.framework/Versions/3.7/lib/python3.7/site-packages/telegram/ext/handler.py", line 120, in handle_update
    return self.callback(dispatcher.bot, update, **optional_args)
  File "botephem.py", line 19, in planets
    someplanet = ephem.myplanet('2019/09/12')
AttributeError: module 'ephem' has no attribute 'myplanet'
telegram.ext.dispatcher - ERROR - No error handlers are registered, logging exception.
Traceback (most recent call last):
  File "/Library/Frameworks/Python.framework/Versions/3.7/lib/python3.7/site-packages/telegram/ext/dispatcher.py", line 372, in process_update
    handler.handle_update(update, self, check, context)
  File "/Library/Frameworks/Python.framework/Versions/3.7/lib/python3.7/site-packages/telegram/ext/handler.py", line 120, in handle_update
    return self.callback(dispatcher.bot, update, **optional_args)
  File "botephem.py", line 17, in planets
    myplanet = message_updates
NameError: name 'message_updates' is not defined
telegram.ext.dispatcher - ERROR - No error handlers are registered, logging exception.
Traceback (most recent call last):
  File "/Library/Frameworks/Python.framework/Versions/3.7/lib/python3.7/site-packages/telegram/ext/dispatcher.py", line 372, in process_update
    handler.handle_update(update, self, check, context)
  File "/Library/Frameworks/Python.framework/Versions/3.7/lib/python3.7/site-packages/telegram/ext/handler.py", line 120, in handle_update
    return self.callback(dispatcher.bot, update, **optional_args)
  File "botephem.py", line 17, in planets
    myplanet = message_updates
NameError: name 'message_updates' is not defined
telegram.ext.dispatcher - ERROR - No error handlers are registered, logging exception.
Traceback (most recent call last):
  File "/Library/Frameworks/Python.framework/Versions/3.7/lib/python3.7/site-packages/telegram/ext/dispatcher.py", line 372, in process_update
    handler.handle_update(update, self, check, context)
  File "/Library/Frameworks/Python.framework/Versions/3.7/lib/python3.7/site-packages/telegram/ext/handler.py", line 120, in handle_update
    return self.callback(dispatcher.bot, update, **optional_args)
  File "botephem.py", line 17, in planets
    myplanet = message_updates
NameError: name 'message_updates' is not defined
telegram.ext.dispatcher - ERROR - No error handlers are registered, logging exception.
Traceback (most recent call last):
  File "/Library/Frameworks/Python.framework/Versions/3.7/lib/python3.7/site-packages/telegram/ext/dispatcher.py", line 372, in process_update
    handler.handle_update(update, self, check, context)
  File "/Library/Frameworks/Python.framework/Versions/3.7/lib/python3.7/site-packages/telegram/ext/handler.py", line 120, in handle_update
    return self.callback(dispatcher.bot, update, **optional_args)
  File "botephem.py", line 17, in planets
    myplanet = update.message.message_updates
AttributeError: 'Message' object has no attribute 'message_updates'
telegram.ext.dispatcher - ERROR - No error handlers are registered, logging exception.
Traceback (most recent call last):
  File "/Library/Frameworks/Python.framework/Versions/3.7/lib/python3.7/site-packages/telegram/ext/dispatcher.py", line 372, in process_update
    handler.handle_update(update, self, check, context)
  File "/Library/Frameworks/Python.framework/Versions/3.7/lib/python3.7/site-packages/telegram/ext/handler.py", line 120, in handle_update
    return self.callback(dispatcher.bot, update, **optional_args)
  File "botephem.py", line 18, in mars
    someplanet = ephem.myplanet('2019/09/12')
AttributeError: module 'ephem' has no attribute 'myplanet'
telegram.ext.dispatcher - ERROR - No error handlers are registered, logging exception.
Traceback (most recent call last):
  File "/Library/Frameworks/Python.framework/Versions/3.7/lib/python3.7/site-packages/telegram/ext/dispatcher.py", line 372, in process_update
    handler.handle_update(update, self, check, context)
  File "/Library/Frameworks/Python.framework/Versions/3.7/lib/python3.7/site-packages/telegram/ext/handler.py", line 120, in handle_update
    return self.callback(dispatcher.bot, update, **optional_args)
  File "botephem.py", line 20, in mars
    update.message.reply_text(someplanet)
  File "/Library/Frameworks/Python.framework/Versions/3.7/lib/python3.7/site-packages/telegram/message.py", line 478, in reply_text
    return self.bot.send_message(self.chat_id, *args, **kwargs)
  File "/Library/Frameworks/Python.framework/Versions/3.7/lib/python3.7/site-packages/telegram/bot.py", line 66, in decorator
    result = func(self, *args, **kwargs)
  File "/Library/Frameworks/Python.framework/Versions/3.7/lib/python3.7/site-packages/telegram/bot.py", line 258, in send_message
    timeout=timeout, **kwargs)
  File "/Library/Frameworks/Python.framework/Versions/3.7/lib/python3.7/site-packages/telegram/bot.py", line 123, in _message
    result = self._request.post(url, data, timeout=timeout)
  File "/Library/Frameworks/Python.framework/Versions/3.7/lib/python3.7/site-packages/telegram/utils/request.py", line 325, in post
    body=json.dumps(data).encode('utf-8'),
  File "/Library/Frameworks/Python.framework/Versions/3.7/lib/python3.7/json/__init__.py", line 231, in dumps
    return _default_encoder.encode(obj)
  File "/Library/Frameworks/Python.framework/Versions/3.7/lib/python3.7/json/encoder.py", line 199, in encode
    chunks = self.iterencode(o, _one_shot=True)
  File "/Library/Frameworks/Python.framework/Versions/3.7/lib/python3.7/json/encoder.py", line 257, in iterencode
    return _iterencode(o, 0)
  File "/Library/Frameworks/Python.framework/Versions/3.7/lib/python3.7/json/encoder.py", line 179, in default
    raise TypeError(f'Object of type {o.__class__.__name__} '
TypeError: Object of type Mars is not JSON serializable
telegram.ext.dispatcher - ERROR - No error handlers are registered, logging exception.
Traceback (most recent call last):
  File "/Library/Frameworks/Python.framework/Versions/3.7/lib/python3.7/site-packages/telegram/ext/dispatcher.py", line 372, in process_update
    handler.handle_update(update, self, check, context)
  File "/Library/Frameworks/Python.framework/Versions/3.7/lib/python3.7/site-packages/telegram/ext/handler.py", line 120, in handle_update
    return self.callback(dispatcher.bot, update, **optional_args)
  File "botephem.py", line 18, in mars
    someplanet = ephem.f(myplanet('2019/09/12'))
AttributeError: module 'ephem' has no attribute 'f'
telegram.ext.dispatcher - ERROR - No error handlers are registered, logging exception.
Traceback (most recent call last):
  File "/Library/Frameworks/Python.framework/Versions/3.7/lib/python3.7/site-packages/telegram/ext/dispatcher.py", line 372, in process_update
    handler.handle_update(update, self, check, context)
  File "/Library/Frameworks/Python.framework/Versions/3.7/lib/python3.7/site-packages/telegram/ext/handler.py", line 120, in handle_update
    return self.callback(dispatcher.bot, update, **optional_args)
  File "botephem.py", line 18, in mars
    someplanet = ephem.f(myplanet)('2019/09/12')
AttributeError: module 'ephem' has no attribute 'f'
telegram.ext.dispatcher - ERROR - No error handlers are registered, logging exception.
Traceback (most recent call last):
  File "/Library/Frameworks/Python.framework/Versions/3.7/lib/python3.7/site-packages/telegram/ext/dispatcher.py", line 372, in process_update
    handler.handle_update(update, self, check, context)
  File "/Library/Frameworks/Python.framework/Versions/3.7/lib/python3.7/site-packages/telegram/ext/handler.py", line 120, in handle_update
    return self.callback(dispatcher.bot, update, **optional_args)
  File "botephem.py", line 18, in mars
    someplanet = ephem.update.message.text('2019/09/12')
AttributeError: module 'ephem' has no attribute 'update'
telegram.ext.dispatcher - ERROR - No error handlers are registered, logging exception.
Traceback (most recent call last):
  File "/Library/Frameworks/Python.framework/Versions/3.7/lib/python3.7/site-packages/telegram/ext/dispatcher.py", line 372, in process_update
    handler.handle_update(update, self, check, context)
  File "/Library/Frameworks/Python.framework/Versions/3.7/lib/python3.7/site-packages/telegram/ext/handler.py", line 120, in handle_update
    return self.callback(dispatcher.bot, update, **optional_args)
  File "botephem.py", line 18, in mars
    someplanet = ephem.format(myplanet=update.message.text)('2019/09/12')
AttributeError: module 'ephem' has no attribute 'format'
telegram.ext.dispatcher - ERROR - No error handlers are registered, logging exception.
Traceback (most recent call last):
  File "/Library/Frameworks/Python.framework/Versions/3.7/lib/python3.7/site-packages/telegram/ext/dispatcher.py", line 372, in process_update
    handler.handle_update(update, self, check, context)
  File "/Library/Frameworks/Python.framework/Versions/3.7/lib/python3.7/site-packages/telegram/ext/handler.py", line 120, in handle_update
    return self.callback(dispatcher.bot, update, **optional_args)
  File "botephem.py", line 18, in mars
    someplanet = ephem.format=('%(myplanet)s')('2019/09/12')
TypeError: 'str' object is not callable
telegram.ext.dispatcher - ERROR - No error handlers are registered, logging exception.
Traceback (most recent call last):
  File "/Library/Frameworks/Python.framework/Versions/3.7/lib/python3.7/site-packages/telegram/ext/dispatcher.py", line 372, in process_update
    handler.handle_update(update, self, check, context)
  File "/Library/Frameworks/Python.framework/Versions/3.7/lib/python3.7/site-packages/telegram/ext/handler.py", line 120, in handle_update
    return self.callback(dispatcher.bot, update, **optional_args)
  File "botephem.py", line 18, in mars
    someplanet = ephem.f('%(myplanet)s')('2019/09/12')
AttributeError: module 'ephem' has no attribute 'f'
telegram.ext.dispatcher - ERROR - No error handlers are registered, logging exception.
Traceback (most recent call last):
  File "/Library/Frameworks/Python.framework/Versions/3.7/lib/python3.7/site-packages/telegram/ext/dispatcher.py", line 372, in process_update
    handler.handle_update(update, self, check, context)
  File "/Library/Frameworks/Python.framework/Versions/3.7/lib/python3.7/site-packages/telegram/ext/handler.py", line 120, in handle_update
    return self.callback(dispatcher.bot, update, **optional_args)
  File "botephem.py", line 18, in mars
    someplanet = ephem(format='.%(myplanet)s')('2019/09/12')
TypeError: 'module' object is not callable
telegram.ext.updater - ERROR - Error while getting Updates: urllib3 HTTPError [SSL: CERTIFICATE_VERIFY_FAILED] certificate verify failed: self signed certificate in certificate chain (_ssl.c:1076)
telegram.ext.dispatcher - ERROR - No error handlers are registered, logging exception.
Traceback (most recent call last):
  File "/Library/Frameworks/Python.framework/Versions/3.7/lib/python3.7/site-packages/telegram/vendor/ptb_urllib3/urllib3/connectionpool.py", line 617, in urlopen
    chunked=chunked)
  File "/Library/Frameworks/Python.framework/Versions/3.7/lib/python3.7/site-packages/telegram/vendor/ptb_urllib3/urllib3/connectionpool.py", line 360, in _make_request
    self._validate_conn(conn)
  File "/Library/Frameworks/Python.framework/Versions/3.7/lib/python3.7/site-packages/telegram/vendor/ptb_urllib3/urllib3/connectionpool.py", line 857, in _validate_conn
    super(HTTPSConnectionPool, self)._validate_conn(conn)
  File "/Library/Frameworks/Python.framework/Versions/3.7/lib/python3.7/site-packages/telegram/vendor/ptb_urllib3/urllib3/connectionpool.py", line 289, in _validate_conn
    conn.connect()
  File "/Library/Frameworks/Python.framework/Versions/3.7/lib/python3.7/site-packages/telegram/vendor/ptb_urllib3/urllib3/connection.py", line 326, in connect
    ssl_context=context)
  File "/Library/Frameworks/Python.framework/Versions/3.7/lib/python3.7/site-packages/telegram/vendor/ptb_urllib3/urllib3/util/ssl_.py", line 324, in ssl_wrap_socket
    return context.wrap_socket(sock, server_hostname=server_hostname)
  File "/Library/Frameworks/Python.framework/Versions/3.7/lib/python3.7/ssl.py", line 423, in wrap_socket
    session=session
  File "/Library/Frameworks/Python.framework/Versions/3.7/lib/python3.7/ssl.py", line 870, in _create
    self.do_handshake()
  File "/Library/Frameworks/Python.framework/Versions/3.7/lib/python3.7/ssl.py", line 1139, in do_handshake
    self._sslobj.do_handshake()
ssl.SSLCertVerificationError: [SSL: CERTIFICATE_VERIFY_FAILED] certificate verify failed: self signed certificate in certificate chain (_ssl.c:1076)

During handling of the above exception, another exception occurred:

Traceback (most recent call last):
  File "/Library/Frameworks/Python.framework/Versions/3.7/lib/python3.7/site-packages/telegram/utils/request.py", line 218, in _request_wrapper
    resp = self._con_pool.request(*args, **kwargs)
  File "/Library/Frameworks/Python.framework/Versions/3.7/lib/python3.7/site-packages/telegram/vendor/ptb_urllib3/urllib3/request.py", line 70, in request
    **urlopen_kw)
  File "/Library/Frameworks/Python.framework/Versions/3.7/lib/python3.7/site-packages/telegram/vendor/ptb_urllib3/urllib3/request.py", line 148, in request_encode_body
    return self.urlopen(method, url, **extra_kw)
  File "/Library/Frameworks/Python.framework/Versions/3.7/lib/python3.7/site-packages/telegram/vendor/ptb_urllib3/urllib3/poolmanager.py", line 244, in urlopen
    response = conn.urlopen(method, u.request_uri, **kw)
  File "/Library/Frameworks/Python.framework/Versions/3.7/lib/python3.7/site-packages/telegram/vendor/ptb_urllib3/urllib3/connectionpool.py", line 647, in urlopen
    raise SSLError(e)
telegram.vendor.ptb_urllib3.urllib3.exceptions.SSLError: [SSL: CERTIFICATE_VERIFY_FAILED] certificate verify failed: self signed certificate in certificate chain (_ssl.c:1076)

During handling of the above exception, another exception occurred:

Traceback (most recent call last):
  File "/Library/Frameworks/Python.framework/Versions/3.7/lib/python3.7/site-packages/telegram/ext/updater.py", line 332, in _network_loop_retry
    if not action_cb():
  File "/Library/Frameworks/Python.framework/Versions/3.7/lib/python3.7/site-packages/telegram/ext/updater.py", line 293, in polling_action_cb
    allowed_updates=allowed_updates)
  File "/Library/Frameworks/Python.framework/Versions/3.7/lib/python3.7/site-packages/telegram/bot.py", line 66, in decorator
    result = func(self, *args, **kwargs)
  File "/Library/Frameworks/Python.framework/Versions/3.7/lib/python3.7/site-packages/telegram/bot.py", line 1982, in get_updates
    result = self._request.post(url, data, timeout=float(read_latency) + float(timeout))
  File "/Library/Frameworks/Python.framework/Versions/3.7/lib/python3.7/site-packages/telegram/utils/request.py", line 327, in post
    **urlopen_kwargs)
  File "/Library/Frameworks/Python.framework/Versions/3.7/lib/python3.7/site-packages/telegram/utils/request.py", line 224, in _request_wrapper
    raise NetworkError('urllib3 HTTPError {0}'.format(error))
telegram.error.NetworkError: urllib3 HTTPError [SSL: CERTIFICATE_VERIFY_FAILED] certificate verify failed: self signed certificate in certificate chain (_ssl.c:1076)
telegram.vendor.ptb_urllib3.urllib3.connectionpool - WARNING - Retrying (Retry(total=2, connect=None, read=None, redirect=None)) after connection broken by 'ConnectTimeoutError(<telegram.vendor.ptb_urllib3.urllib3.connection.VerifiedHTTPSConnection object at 0x10960fcd0>, 'Connection to api.telegram.org timed out. (connect timeout=5.0)')': /bot808049629:AAHXH6XLn_2HpMGsgUBn9y0TCI2mn22mJ8A/getUpdates
telegram.vendor.ptb_urllib3.urllib3.connectionpool - WARNING - Retrying (Retry(total=1, connect=None, read=None, redirect=None)) after connection broken by 'ConnectTimeoutError(<telegram.vendor.ptb_urllib3.urllib3.connection.VerifiedHTTPSConnection object at 0x109643410>, 'Connection to api.telegram.org timed out. (connect timeout=5.0)')': /bot808049629:AAHXH6XLn_2HpMGsgUBn9y0TCI2mn22mJ8A/getUpdates
telegram.vendor.ptb_urllib3.urllib3.connectionpool - WARNING - Retrying (Retry(total=0, connect=None, read=None, redirect=None)) after connection broken by 'ConnectTimeoutError(<telegram.vendor.ptb_urllib3.urllib3.connection.VerifiedHTTPSConnection object at 0x1096f7190>, 'Connection to api.telegram.org timed out. (connect timeout=5.0)')': /bot808049629:AAHXH6XLn_2HpMGsgUBn9y0TCI2mn22mJ8A/getUpdates
telegram.ext.dispatcher - ERROR - No error handlers are registered, logging exception.
Traceback (most recent call last):
  File "/Library/Frameworks/Python.framework/Versions/3.7/lib/python3.7/site-packages/telegram/ext/dispatcher.py", line 372, in process_update
    handler.handle_update(update, self, check, context)
  File "/Library/Frameworks/Python.framework/Versions/3.7/lib/python3.7/site-packages/telegram/ext/handler.py", line 120, in handle_update
    return self.callback(dispatcher.bot, update, **optional_args)
  File "botephem.py", line 17, in mars
    if myplanet == Mars:
NameError: name 'Mars' is not defined
telegram.ext.dispatcher - ERROR - No error handlers are registered, logging exception.
Traceback (most recent call last):
  File "/Library/Frameworks/Python.framework/Versions/3.7/lib/python3.7/site-packages/telegram/ext/dispatcher.py", line 372, in process_update
    handler.handle_update(update, self, check, context)
  File "/Library/Frameworks/Python.framework/Versions/3.7/lib/python3.7/site-packages/telegram/ext/handler.py", line 120, in handle_update
    return self.callback(dispatcher.bot, update, **optional_args)
  File "botephem.py", line 20, in mars
    update.message.reply_text(mymars)
  File "/Library/Frameworks/Python.framework/Versions/3.7/lib/python3.7/site-packages/telegram/message.py", line 478, in reply_text
    return self.bot.send_message(self.chat_id, *args, **kwargs)
  File "/Library/Frameworks/Python.framework/Versions/3.7/lib/python3.7/site-packages/telegram/bot.py", line 66, in decorator
    result = func(self, *args, **kwargs)
  File "/Library/Frameworks/Python.framework/Versions/3.7/lib/python3.7/site-packages/telegram/bot.py", line 258, in send_message
    timeout=timeout, **kwargs)
  File "/Library/Frameworks/Python.framework/Versions/3.7/lib/python3.7/site-packages/telegram/bot.py", line 123, in _message
    result = self._request.post(url, data, timeout=timeout)
  File "/Library/Frameworks/Python.framework/Versions/3.7/lib/python3.7/site-packages/telegram/utils/request.py", line 325, in post
    body=json.dumps(data).encode('utf-8'),
  File "/Library/Frameworks/Python.framework/Versions/3.7/lib/python3.7/json/__init__.py", line 231, in dumps
    return _default_encoder.encode(obj)
  File "/Library/Frameworks/Python.framework/Versions/3.7/lib/python3.7/json/encoder.py", line 199, in encode
    chunks = self.iterencode(o, _one_shot=True)
  File "/Library/Frameworks/Python.framework/Versions/3.7/lib/python3.7/json/encoder.py", line 257, in iterencode
    return _iterencode(o, 0)
  File "/Library/Frameworks/Python.framework/Versions/3.7/lib/python3.7/json/encoder.py", line 179, in default
    raise TypeError(f'Object of type {o.__class__.__name__} '
TypeError: Object of type Mars is not JSON serializable
telegram.ext.dispatcher - ERROR - No error handlers are registered, logging exception.
Traceback (most recent call last):
  File "/Library/Frameworks/Python.framework/Versions/3.7/lib/python3.7/site-packages/telegram/ext/dispatcher.py", line 372, in process_update
    handler.handle_update(update, self, check, context)
  File "/Library/Frameworks/Python.framework/Versions/3.7/lib/python3.7/site-packages/telegram/ext/handler.py", line 120, in handle_update
    return self.callback(dispatcher.bot, update, **optional_args)
  File "botephem.py", line 39, in mars
    update.message.reply_text(myPluto)
  File "/Library/Frameworks/Python.framework/Versions/3.7/lib/python3.7/site-packages/telegram/message.py", line 478, in reply_text
    return self.bot.send_message(self.chat_id, *args, **kwargs)
  File "/Library/Frameworks/Python.framework/Versions/3.7/lib/python3.7/site-packages/telegram/bot.py", line 66, in decorator
    result = func(self, *args, **kwargs)
  File "/Library/Frameworks/Python.framework/Versions/3.7/lib/python3.7/site-packages/telegram/bot.py", line 258, in send_message
    timeout=timeout, **kwargs)
  File "/Library/Frameworks/Python.framework/Versions/3.7/lib/python3.7/site-packages/telegram/bot.py", line 123, in _message
    result = self._request.post(url, data, timeout=timeout)
  File "/Library/Frameworks/Python.framework/Versions/3.7/lib/python3.7/site-packages/telegram/utils/request.py", line 325, in post
    body=json.dumps(data).encode('utf-8'),
  File "/Library/Frameworks/Python.framework/Versions/3.7/lib/python3.7/json/__init__.py", line 231, in dumps
    return _default_encoder.encode(obj)
  File "/Library/Frameworks/Python.framework/Versions/3.7/lib/python3.7/json/encoder.py", line 199, in encode
    chunks = self.iterencode(o, _one_shot=True)
  File "/Library/Frameworks/Python.framework/Versions/3.7/lib/python3.7/json/encoder.py", line 257, in iterencode
    return _iterencode(o, 0)
  File "/Library/Frameworks/Python.framework/Versions/3.7/lib/python3.7/json/encoder.py", line 179, in default
    raise TypeError(f'Object of type {o.__class__.__name__} '
TypeError: Object of type Pluto is not JSON serializable
telegram.ext.dispatcher - ERROR - No error handlers are registered, logging exception.
Traceback (most recent call last):
  File "/Library/Frameworks/Python.framework/Versions/3.7/lib/python3.7/site-packages/telegram/ext/dispatcher.py", line 372, in process_update
    handler.handle_update(update, self, check, context)
  File "/Library/Frameworks/Python.framework/Versions/3.7/lib/python3.7/site-packages/telegram/ext/handler.py", line 120, in handle_update
    return self.callback(dispatcher.bot, update, **optional_args)
  File "botephem.py", line 18, in mars
    update.message.reply_text(mymars)
  File "/Library/Frameworks/Python.framework/Versions/3.7/lib/python3.7/site-packages/telegram/message.py", line 478, in reply_text
    return self.bot.send_message(self.chat_id, *args, **kwargs)
  File "/Library/Frameworks/Python.framework/Versions/3.7/lib/python3.7/site-packages/telegram/bot.py", line 66, in decorator
    result = func(self, *args, **kwargs)
  File "/Library/Frameworks/Python.framework/Versions/3.7/lib/python3.7/site-packages/telegram/bot.py", line 258, in send_message
    timeout=timeout, **kwargs)
  File "/Library/Frameworks/Python.framework/Versions/3.7/lib/python3.7/site-packages/telegram/bot.py", line 123, in _message
    result = self._request.post(url, data, timeout=timeout)
  File "/Library/Frameworks/Python.framework/Versions/3.7/lib/python3.7/site-packages/telegram/utils/request.py", line 325, in post
    body=json.dumps(data).encode('utf-8'),
  File "/Library/Frameworks/Python.framework/Versions/3.7/lib/python3.7/json/__init__.py", line 231, in dumps
    return _default_encoder.encode(obj)
  File "/Library/Frameworks/Python.framework/Versions/3.7/lib/python3.7/json/encoder.py", line 199, in encode
    chunks = self.iterencode(o, _one_shot=True)
  File "/Library/Frameworks/Python.framework/Versions/3.7/lib/python3.7/json/encoder.py", line 257, in iterencode
    return _iterencode(o, 0)
  File "/Library/Frameworks/Python.framework/Versions/3.7/lib/python3.7/json/encoder.py", line 179, in default
    raise TypeError(f'Object of type {o.__class__.__name__} '
TypeError: Object of type Mars is not JSON serializable
telegram.ext.dispatcher - ERROR - No error handlers are registered, logging exception.
Traceback (most recent call last):
  File "/Library/Frameworks/Python.framework/Versions/3.7/lib/python3.7/site-packages/telegram/ext/dispatcher.py", line 372, in process_update
    handler.handle_update(update, self, check, context)
  File "/Library/Frameworks/Python.framework/Versions/3.7/lib/python3.7/site-packages/telegram/ext/handler.py", line 120, in handle_update
    return self.callback(dispatcher.bot, update, **optional_args)
  File "botephem.py", line 19, in mars
    update.message.reply_text(mymars)
  File "/Library/Frameworks/Python.framework/Versions/3.7/lib/python3.7/site-packages/telegram/message.py", line 478, in reply_text
    return self.bot.send_message(self.chat_id, *args, **kwargs)
  File "/Library/Frameworks/Python.framework/Versions/3.7/lib/python3.7/site-packages/telegram/bot.py", line 66, in decorator
    result = func(self, *args, **kwargs)
  File "/Library/Frameworks/Python.framework/Versions/3.7/lib/python3.7/site-packages/telegram/bot.py", line 258, in send_message
    timeout=timeout, **kwargs)
  File "/Library/Frameworks/Python.framework/Versions/3.7/lib/python3.7/site-packages/telegram/bot.py", line 123, in _message
    result = self._request.post(url, data, timeout=timeout)
  File "/Library/Frameworks/Python.framework/Versions/3.7/lib/python3.7/site-packages/telegram/utils/request.py", line 325, in post
    body=json.dumps(data).encode('utf-8'),
  File "/Library/Frameworks/Python.framework/Versions/3.7/lib/python3.7/json/__init__.py", line 231, in dumps
    return _default_encoder.encode(obj)
  File "/Library/Frameworks/Python.framework/Versions/3.7/lib/python3.7/json/encoder.py", line 199, in encode
    chunks = self.iterencode(o, _one_shot=True)
  File "/Library/Frameworks/Python.framework/Versions/3.7/lib/python3.7/json/encoder.py", line 257, in iterencode
    return _iterencode(o, 0)
  File "/Library/Frameworks/Python.framework/Versions/3.7/lib/python3.7/json/encoder.py", line 179, in default
    raise TypeError(f'Object of type {o.__class__.__name__} '
TypeError: Object of type Mars is not JSON serializable
telegram.ext.dispatcher - ERROR - No error handlers are registered, logging exception.
Traceback (most recent call last):
  File "/Library/Frameworks/Python.framework/Versions/3.7/lib/python3.7/site-packages/telegram/ext/dispatcher.py", line 372, in process_update
    handler.handle_update(update, self, check, context)
  File "/Library/Frameworks/Python.framework/Versions/3.7/lib/python3.7/site-packages/telegram/ext/handler.py", line 120, in handle_update
    return self.callback(dispatcher.bot, update, **optional_args)
  File "botephem.py", line 20, in mars
    update.message.reply_text(mymars)
  File "/Library/Frameworks/Python.framework/Versions/3.7/lib/python3.7/site-packages/telegram/message.py", line 478, in reply_text
    return self.bot.send_message(self.chat_id, *args, **kwargs)
  File "/Library/Frameworks/Python.framework/Versions/3.7/lib/python3.7/site-packages/telegram/bot.py", line 66, in decorator
    result = func(self, *args, **kwargs)
  File "/Library/Frameworks/Python.framework/Versions/3.7/lib/python3.7/site-packages/telegram/bot.py", line 258, in send_message
    timeout=timeout, **kwargs)
  File "/Library/Frameworks/Python.framework/Versions/3.7/lib/python3.7/site-packages/telegram/bot.py", line 123, in _message
    result = self._request.post(url, data, timeout=timeout)
  File "/Library/Frameworks/Python.framework/Versions/3.7/lib/python3.7/site-packages/telegram/utils/request.py", line 325, in post
    body=json.dumps(data).encode('utf-8'),
  File "/Library/Frameworks/Python.framework/Versions/3.7/lib/python3.7/json/__init__.py", line 231, in dumps
    return _default_encoder.encode(obj)
  File "/Library/Frameworks/Python.framework/Versions/3.7/lib/python3.7/json/encoder.py", line 199, in encode
    chunks = self.iterencode(o, _one_shot=True)
  File "/Library/Frameworks/Python.framework/Versions/3.7/lib/python3.7/json/encoder.py", line 257, in iterencode
    return _iterencode(o, 0)
  File "/Library/Frameworks/Python.framework/Versions/3.7/lib/python3.7/json/encoder.py", line 179, in default
    raise TypeError(f'Object of type {o.__class__.__name__} '
TypeError: Object of type Mars is not JSON serializable
telegram.ext.dispatcher - ERROR - No error handlers are registered, logging exception.
Traceback (most recent call last):
  File "/Library/Frameworks/Python.framework/Versions/3.7/lib/python3.7/site-packages/telegram/ext/dispatcher.py", line 372, in process_update
    handler.handle_update(update, self, check, context)
  File "/Library/Frameworks/Python.framework/Versions/3.7/lib/python3.7/site-packages/telegram/ext/handler.py", line 120, in handle_update
    return self.callback(dispatcher.bot, update, **optional_args)
  File "botephem.py", line 20, in mars
    update.message.reply_text(mymars)
  File "/Library/Frameworks/Python.framework/Versions/3.7/lib/python3.7/site-packages/telegram/message.py", line 478, in reply_text
    return self.bot.send_message(self.chat_id, *args, **kwargs)
  File "/Library/Frameworks/Python.framework/Versions/3.7/lib/python3.7/site-packages/telegram/bot.py", line 66, in decorator
    result = func(self, *args, **kwargs)
  File "/Library/Frameworks/Python.framework/Versions/3.7/lib/python3.7/site-packages/telegram/bot.py", line 258, in send_message
    timeout=timeout, **kwargs)
  File "/Library/Frameworks/Python.framework/Versions/3.7/lib/python3.7/site-packages/telegram/bot.py", line 123, in _message
    result = self._request.post(url, data, timeout=timeout)
  File "/Library/Frameworks/Python.framework/Versions/3.7/lib/python3.7/site-packages/telegram/utils/request.py", line 325, in post
    body=json.dumps(data).encode('utf-8'),
  File "/Library/Frameworks/Python.framework/Versions/3.7/lib/python3.7/json/__init__.py", line 231, in dumps
    return _default_encoder.encode(obj)
  File "/Library/Frameworks/Python.framework/Versions/3.7/lib/python3.7/json/encoder.py", line 199, in encode
    chunks = self.iterencode(o, _one_shot=True)
  File "/Library/Frameworks/Python.framework/Versions/3.7/lib/python3.7/json/encoder.py", line 257, in iterencode
    return _iterencode(o, 0)
  File "/Library/Frameworks/Python.framework/Versions/3.7/lib/python3.7/json/encoder.py", line 179, in default
    raise TypeError(f'Object of type {o.__class__.__name__} '
TypeError: Object of type Mars is not JSON serializable
telegram.ext.dispatcher - ERROR - No error handlers are registered, logging exception.
Traceback (most recent call last):
  File "/Library/Frameworks/Python.framework/Versions/3.7/lib/python3.7/site-packages/telegram/ext/dispatcher.py", line 372, in process_update
    handler.handle_update(update, self, check, context)
  File "/Library/Frameworks/Python.framework/Versions/3.7/lib/python3.7/site-packages/telegram/ext/handler.py", line 120, in handle_update
    return self.callback(dispatcher.bot, update, **optional_args)
  File "botephem.py", line 20, in mars
    update.message.reply_text(mymars)
  File "/Library/Frameworks/Python.framework/Versions/3.7/lib/python3.7/site-packages/telegram/message.py", line 478, in reply_text
    return self.bot.send_message(self.chat_id, *args, **kwargs)
  File "/Library/Frameworks/Python.framework/Versions/3.7/lib/python3.7/site-packages/telegram/bot.py", line 66, in decorator
    result = func(self, *args, **kwargs)
  File "/Library/Frameworks/Python.framework/Versions/3.7/lib/python3.7/site-packages/telegram/bot.py", line 258, in send_message
    timeout=timeout, **kwargs)
  File "/Library/Frameworks/Python.framework/Versions/3.7/lib/python3.7/site-packages/telegram/bot.py", line 123, in _message
    result = self._request.post(url, data, timeout=timeout)
  File "/Library/Frameworks/Python.framework/Versions/3.7/lib/python3.7/site-packages/telegram/utils/request.py", line 325, in post
    body=json.dumps(data).encode('utf-8'),
  File "/Library/Frameworks/Python.framework/Versions/3.7/lib/python3.7/json/__init__.py", line 231, in dumps
    return _default_encoder.encode(obj)
  File "/Library/Frameworks/Python.framework/Versions/3.7/lib/python3.7/json/encoder.py", line 199, in encode
    chunks = self.iterencode(o, _one_shot=True)
  File "/Library/Frameworks/Python.framework/Versions/3.7/lib/python3.7/json/encoder.py", line 257, in iterencode
    return _iterencode(o, 0)
  File "/Library/Frameworks/Python.framework/Versions/3.7/lib/python3.7/json/encoder.py", line 179, in default
    raise TypeError(f'Object of type {o.__class__.__name__} '
TypeError: Object of type Mars is not JSON serializable
telegram.ext.dispatcher - ERROR - No error handlers are registered, logging exception.
Traceback (most recent call last):
  File "/Library/Frameworks/Python.framework/Versions/3.7/lib/python3.7/site-packages/telegram/ext/dispatcher.py", line 372, in process_update
    handler.handle_update(update, self, check, context)
  File "/Library/Frameworks/Python.framework/Versions/3.7/lib/python3.7/site-packages/telegram/ext/handler.py", line 120, in handle_update
    return self.callback(dispatcher.bot, update, **optional_args)
  File "botephem.py", line 18, in mars
    mymars = ephem.Mars('%Y/%m/%d')
ValueError: your date string  does not look like a year/month/day optionally followed by hours:minutes:seconds
telegram.ext.dispatcher - ERROR - No error handlers are registered, logging exception.
Traceback (most recent call last):
  File "/Library/Frameworks/Python.framework/Versions/3.7/lib/python3.7/site-packages/telegram/ext/dispatcher.py", line 372, in process_update
    handler.handle_update(update, self, check, context)
  File "/Library/Frameworks/Python.framework/Versions/3.7/lib/python3.7/site-packages/telegram/ext/handler.py", line 120, in handle_update
    return self.callback(dispatcher.bot, update, **optional_args)
  File "botephem.py", line 18, in mars
    mymars = ephem.Mars('% now.day')
ValueError: your date string  does not look like a year/month/day optionally followed by hours:minutes:seconds
telegram.ext.dispatcher - ERROR - No error handlers are registered, logging exception.
Traceback (most recent call last):
  File "/Library/Frameworks/Python.framework/Versions/3.7/lib/python3.7/site-packages/telegram/ext/dispatcher.py", line 372, in process_update
    handler.handle_update(update, self, check, context)
  File "/Library/Frameworks/Python.framework/Versions/3.7/lib/python3.7/site-packages/telegram/ext/handler.py", line 120, in handle_update
    return self.callback(dispatcher.bot, update, **optional_args)
  File "botephem.py", line 18, in mars
    mymars = ephem.Mars(datetime.today())
NameError: name 'datetime' is not defined
telegram.ext.dispatcher - ERROR - No error handlers are registered, logging exception.
Traceback (most recent call last):
  File "/Library/Frameworks/Python.framework/Versions/3.7/lib/python3.7/site-packages/telegram/ext/dispatcher.py", line 372, in process_update
    handler.handle_update(update, self, check, context)
  File "/Library/Frameworks/Python.framework/Versions/3.7/lib/python3.7/site-packages/telegram/ext/handler.py", line 120, in handle_update
    return self.callback(dispatcher.bot, update, **optional_args)
  File "botephem.py", line 18, in mars
    mymars = ephem.Mars('%Y/%M/%D')
ValueError: your date string  does not look like a year/month/day optionally followed by hours:minutes:seconds
telegram.ext.dispatcher - ERROR - No error handlers are registered, logging exception.
Traceback (most recent call last):
  File "/Library/Frameworks/Python.framework/Versions/3.7/lib/python3.7/site-packages/telegram/ext/dispatcher.py", line 372, in process_update
    handler.handle_update(update, self, check, context)
  File "/Library/Frameworks/Python.framework/Versions/3.7/lib/python3.7/site-packages/telegram/ext/handler.py", line 120, in handle_update
    return self.callback(dispatcher.bot, update, **optional_args)
  File "botephem.py", line 15, in mars
    now = now.strftime('%Y/%m/%d')
UnboundLocalError: local variable 'now' referenced before assignment
telegram.ext.dispatcher - ERROR - No error handlers are registered, logging exception.
Traceback (most recent call last):
  File "/Library/Frameworks/Python.framework/Versions/3.7/lib/python3.7/site-packages/telegram/ext/dispatcher.py", line 372, in process_update
    handler.handle_update(update, self, check, context)
  File "/Library/Frameworks/Python.framework/Versions/3.7/lib/python3.7/site-packages/telegram/ext/handler.py", line 120, in handle_update
    return self.callback(dispatcher.bot, update, **optional_args)
  File "botephem.py", line 15, in mars
    now = now.strftime('%Y-%m-%d')
UnboundLocalError: local variable 'now' referenced before assignment
telegram.vendor.ptb_urllib3.urllib3.connectionpool - WARNING - Retrying (Retry(total=2, connect=None, read=None, redirect=None)) after connection broken by 'ConnectTimeoutError(<telegram.vendor.ptb_urllib3.urllib3.connection.VerifiedHTTPSConnection object at 0x110789ed0>, 'Connection to api.telegram.org timed out. (connect timeout=5.0)')': /bot808049629:AAHXH6XLn_2HpMGsgUBn9y0TCI2mn22mJ8A/getUpdates
telegram.vendor.ptb_urllib3.urllib3.connectionpool - WARNING - Retrying (Retry(total=1, connect=None, read=None, redirect=None)) after connection broken by 'ConnectTimeoutError(<telegram.vendor.ptb_urllib3.urllib3.connection.VerifiedHTTPSConnection object at 0x110901210>, 'Connection to api.telegram.org timed out. (connect timeout=5.0)')': /bot808049629:AAHXH6XLn_2HpMGsgUBn9y0TCI2mn22mJ8A/getUpdates
telegram.vendor.ptb_urllib3.urllib3.connectionpool - WARNING - Retrying (Retry(total=0, connect=None, read=None, redirect=None)) after connection broken by 'NewConnectionError('<telegram.vendor.ptb_urllib3.urllib3.connection.VerifiedHTTPSConnection object at 0x110901350>: Failed to establish a new connection: [Errno 8] nodename nor servname provided, or not known')': /bot808049629:AAHXH6XLn_2HpMGsgUBn9y0TCI2mn22mJ8A/getUpdates
telegram.ext.updater - ERROR - Error while getting Updates: urllib3 HTTPError HTTPSConnectionPool(host='api.telegram.org', port=443): Max retries exceeded with url: /bot808049629:AAHXH6XLn_2HpMGsgUBn9y0TCI2mn22mJ8A/getUpdates (Caused by NewConnectionError('<telegram.vendor.ptb_urllib3.urllib3.connection.VerifiedHTTPSConnection object at 0x110901510>: Failed to establish a new connection: [Errno 8] nodename nor servname provided, or not known'))
telegram.ext.dispatcher - ERROR - No error handlers are registered, logging exception.
Traceback (most recent call last):
  File "/Library/Frameworks/Python.framework/Versions/3.7/lib/python3.7/site-packages/telegram/vendor/ptb_urllib3/urllib3/connection.py", line 141, in _new_conn
    (self.host, self.port), self.timeout, **extra_kw)
  File "/Library/Frameworks/Python.framework/Versions/3.7/lib/python3.7/site-packages/telegram/vendor/ptb_urllib3/urllib3/util/connection.py", line 60, in create_connection
    for res in socket.getaddrinfo(host, port, family, socket.SOCK_STREAM):
  File "/Library/Frameworks/Python.framework/Versions/3.7/lib/python3.7/socket.py", line 748, in getaddrinfo
    for res in _socket.getaddrinfo(host, port, family, type, proto, flags):
socket.gaierror: [Errno 8] nodename nor servname provided, or not known

During handling of the above exception, another exception occurred:

Traceback (most recent call last):
  File "/Library/Frameworks/Python.framework/Versions/3.7/lib/python3.7/site-packages/telegram/vendor/ptb_urllib3/urllib3/connectionpool.py", line 617, in urlopen
    chunked=chunked)
  File "/Library/Frameworks/Python.framework/Versions/3.7/lib/python3.7/site-packages/telegram/vendor/ptb_urllib3/urllib3/connectionpool.py", line 360, in _make_request
    self._validate_conn(conn)
  File "/Library/Frameworks/Python.framework/Versions/3.7/lib/python3.7/site-packages/telegram/vendor/ptb_urllib3/urllib3/connectionpool.py", line 857, in _validate_conn
    super(HTTPSConnectionPool, self)._validate_conn(conn)
  File "/Library/Frameworks/Python.framework/Versions/3.7/lib/python3.7/site-packages/telegram/vendor/ptb_urllib3/urllib3/connectionpool.py", line 289, in _validate_conn
    conn.connect()
  File "/Library/Frameworks/Python.framework/Versions/3.7/lib/python3.7/site-packages/telegram/vendor/ptb_urllib3/urllib3/connection.py", line 284, in connect
    conn = self._new_conn()
  File "/Library/Frameworks/Python.framework/Versions/3.7/lib/python3.7/site-packages/telegram/vendor/ptb_urllib3/urllib3/connection.py", line 150, in _new_conn
    self, "Failed to establish a new connection: %s" % e)
telegram.vendor.ptb_urllib3.urllib3.exceptions.NewConnectionError: <telegram.vendor.ptb_urllib3.urllib3.connection.VerifiedHTTPSConnection object at 0x110901510>: Failed to establish a new connection: [Errno 8] nodename nor servname provided, or not known

During handling of the above exception, another exception occurred:

Traceback (most recent call last):
  File "/Library/Frameworks/Python.framework/Versions/3.7/lib/python3.7/site-packages/telegram/utils/request.py", line 218, in _request_wrapper
    resp = self._con_pool.request(*args, **kwargs)
  File "/Library/Frameworks/Python.framework/Versions/3.7/lib/python3.7/site-packages/telegram/vendor/ptb_urllib3/urllib3/request.py", line 70, in request
    **urlopen_kw)
  File "/Library/Frameworks/Python.framework/Versions/3.7/lib/python3.7/site-packages/telegram/vendor/ptb_urllib3/urllib3/request.py", line 148, in request_encode_body
    return self.urlopen(method, url, **extra_kw)
  File "/Library/Frameworks/Python.framework/Versions/3.7/lib/python3.7/site-packages/telegram/vendor/ptb_urllib3/urllib3/poolmanager.py", line 244, in urlopen
    response = conn.urlopen(method, u.request_uri, **kw)
  File "/Library/Frameworks/Python.framework/Versions/3.7/lib/python3.7/site-packages/telegram/vendor/ptb_urllib3/urllib3/connectionpool.py", line 695, in urlopen
    **response_kw)
  File "/Library/Frameworks/Python.framework/Versions/3.7/lib/python3.7/site-packages/telegram/vendor/ptb_urllib3/urllib3/connectionpool.py", line 695, in urlopen
    **response_kw)
  File "/Library/Frameworks/Python.framework/Versions/3.7/lib/python3.7/site-packages/telegram/vendor/ptb_urllib3/urllib3/connectionpool.py", line 695, in urlopen
    **response_kw)
  File "/Library/Frameworks/Python.framework/Versions/3.7/lib/python3.7/site-packages/telegram/vendor/ptb_urllib3/urllib3/connectionpool.py", line 666, in urlopen
    _stacktrace=sys.exc_info()[2])
  File "/Library/Frameworks/Python.framework/Versions/3.7/lib/python3.7/site-packages/telegram/vendor/ptb_urllib3/urllib3/util/retry.py", line 376, in increment
    raise MaxRetryError(_pool, url, error or ResponseError(cause))
telegram.vendor.ptb_urllib3.urllib3.exceptions.MaxRetryError: HTTPSConnectionPool(host='api.telegram.org', port=443): Max retries exceeded with url: /bot808049629:AAHXH6XLn_2HpMGsgUBn9y0TCI2mn22mJ8A/getUpdates (Caused by NewConnectionError('<telegram.vendor.ptb_urllib3.urllib3.connection.VerifiedHTTPSConnection object at 0x110901510>: Failed to establish a new connection: [Errno 8] nodename nor servname provided, or not known'))

During handling of the above exception, another exception occurred:

Traceback (most recent call last):
  File "/Library/Frameworks/Python.framework/Versions/3.7/lib/python3.7/site-packages/telegram/ext/updater.py", line 332, in _network_loop_retry
    if not action_cb():
  File "/Library/Frameworks/Python.framework/Versions/3.7/lib/python3.7/site-packages/telegram/ext/updater.py", line 293, in polling_action_cb
    allowed_updates=allowed_updates)
  File "/Library/Frameworks/Python.framework/Versions/3.7/lib/python3.7/site-packages/telegram/bot.py", line 66, in decorator
    result = func(self, *args, **kwargs)
  File "/Library/Frameworks/Python.framework/Versions/3.7/lib/python3.7/site-packages/telegram/bot.py", line 1982, in get_updates
    result = self._request.post(url, data, timeout=float(read_latency) + float(timeout))
  File "/Library/Frameworks/Python.framework/Versions/3.7/lib/python3.7/site-packages/telegram/utils/request.py", line 327, in post
    **urlopen_kwargs)
  File "/Library/Frameworks/Python.framework/Versions/3.7/lib/python3.7/site-packages/telegram/utils/request.py", line 224, in _request_wrapper
    raise NetworkError('urllib3 HTTPError {0}'.format(error))
telegram.error.NetworkError: urllib3 HTTPError HTTPSConnectionPool(host='api.telegram.org', port=443): Max retries exceeded with url: /bot808049629:AAHXH6XLn_2HpMGsgUBn9y0TCI2mn22mJ8A/getUpdates (Caused by NewConnectionError('<telegram.vendor.ptb_urllib3.urllib3.connection.VerifiedHTTPSConnection object at 0x110901510>: Failed to establish a new connection: [Errno 8] nodename nor servname provided, or not known'))
telegram.vendor.ptb_urllib3.urllib3.connectionpool - WARNING - Retrying (Retry(total=2, connect=None, read=None, redirect=None)) after connection broken by 'NewConnectionError('<telegram.vendor.ptb_urllib3.urllib3.connection.VerifiedHTTPSConnection object at 0x1109016d0>: Failed to establish a new connection: [Errno 8] nodename nor servname provided, or not known')': /bot808049629:AAHXH6XLn_2HpMGsgUBn9y0TCI2mn22mJ8A/getUpdates
telegram.vendor.ptb_urllib3.urllib3.connectionpool - WARNING - Retrying (Retry(total=1, connect=None, read=None, redirect=None)) after connection broken by 'NewConnectionError('<telegram.vendor.ptb_urllib3.urllib3.connection.VerifiedHTTPSConnection object at 0x110901990>: Failed to establish a new connection: [Errno 8] nodename nor servname provided, or not known')': /bot808049629:AAHXH6XLn_2HpMGsgUBn9y0TCI2mn22mJ8A/getUpdates
telegram.vendor.ptb_urllib3.urllib3.connectionpool - WARNING - Retrying (Retry(total=0, connect=None, read=None, redirect=None)) after connection broken by 'NewConnectionError('<telegram.vendor.ptb_urllib3.urllib3.connection.VerifiedHTTPSConnection object at 0x1109c4f90>: Failed to establish a new connection: [Errno 8] nodename nor servname provided, or not known')': /bot808049629:AAHXH6XLn_2HpMGsgUBn9y0TCI2mn22mJ8A/getUpdates
telegram.ext.updater - ERROR - Error while getting Updates: urllib3 HTTPError HTTPSConnectionPool(host='api.telegram.org', port=443): Max retries exceeded with url: /bot808049629:AAHXH6XLn_2HpMGsgUBn9y0TCI2mn22mJ8A/getUpdates (Caused by NewConnectionError('<telegram.vendor.ptb_urllib3.urllib3.connection.VerifiedHTTPSConnection object at 0x1109e9e10>: Failed to establish a new connection: [Errno 8] nodename nor servname provided, or not known'))
telegram.ext.dispatcher - ERROR - No error handlers are registered, logging exception.
Traceback (most recent call last):
  File "/Library/Frameworks/Python.framework/Versions/3.7/lib/python3.7/site-packages/telegram/vendor/ptb_urllib3/urllib3/connection.py", line 141, in _new_conn
    (self.host, self.port), self.timeout, **extra_kw)
  File "/Library/Frameworks/Python.framework/Versions/3.7/lib/python3.7/site-packages/telegram/vendor/ptb_urllib3/urllib3/util/connection.py", line 60, in create_connection
    for res in socket.getaddrinfo(host, port, family, socket.SOCK_STREAM):
  File "/Library/Frameworks/Python.framework/Versions/3.7/lib/python3.7/socket.py", line 748, in getaddrinfo
    for res in _socket.getaddrinfo(host, port, family, type, proto, flags):
socket.gaierror: [Errno 8] nodename nor servname provided, or not known

During handling of the above exception, another exception occurred:

Traceback (most recent call last):
  File "/Library/Frameworks/Python.framework/Versions/3.7/lib/python3.7/site-packages/telegram/vendor/ptb_urllib3/urllib3/connectionpool.py", line 617, in urlopen
    chunked=chunked)
  File "/Library/Frameworks/Python.framework/Versions/3.7/lib/python3.7/site-packages/telegram/vendor/ptb_urllib3/urllib3/connectionpool.py", line 360, in _make_request
    self._validate_conn(conn)
  File "/Library/Frameworks/Python.framework/Versions/3.7/lib/python3.7/site-packages/telegram/vendor/ptb_urllib3/urllib3/connectionpool.py", line 857, in _validate_conn
    super(HTTPSConnectionPool, self)._validate_conn(conn)
  File "/Library/Frameworks/Python.framework/Versions/3.7/lib/python3.7/site-packages/telegram/vendor/ptb_urllib3/urllib3/connectionpool.py", line 289, in _validate_conn
    conn.connect()
  File "/Library/Frameworks/Python.framework/Versions/3.7/lib/python3.7/site-packages/telegram/vendor/ptb_urllib3/urllib3/connection.py", line 284, in connect
    conn = self._new_conn()
  File "/Library/Frameworks/Python.framework/Versions/3.7/lib/python3.7/site-packages/telegram/vendor/ptb_urllib3/urllib3/connection.py", line 150, in _new_conn
    self, "Failed to establish a new connection: %s" % e)
telegram.vendor.ptb_urllib3.urllib3.exceptions.NewConnectionError: <telegram.vendor.ptb_urllib3.urllib3.connection.VerifiedHTTPSConnection object at 0x1109e9e10>: Failed to establish a new connection: [Errno 8] nodename nor servname provided, or not known

During handling of the above exception, another exception occurred:

Traceback (most recent call last):
  File "/Library/Frameworks/Python.framework/Versions/3.7/lib/python3.7/site-packages/telegram/utils/request.py", line 218, in _request_wrapper
    resp = self._con_pool.request(*args, **kwargs)
  File "/Library/Frameworks/Python.framework/Versions/3.7/lib/python3.7/site-packages/telegram/vendor/ptb_urllib3/urllib3/request.py", line 70, in request
    **urlopen_kw)
  File "/Library/Frameworks/Python.framework/Versions/3.7/lib/python3.7/site-packages/telegram/vendor/ptb_urllib3/urllib3/request.py", line 148, in request_encode_body
    return self.urlopen(method, url, **extra_kw)
  File "/Library/Frameworks/Python.framework/Versions/3.7/lib/python3.7/site-packages/telegram/vendor/ptb_urllib3/urllib3/poolmanager.py", line 244, in urlopen
    response = conn.urlopen(method, u.request_uri, **kw)
  File "/Library/Frameworks/Python.framework/Versions/3.7/lib/python3.7/site-packages/telegram/vendor/ptb_urllib3/urllib3/connectionpool.py", line 695, in urlopen
    **response_kw)
  File "/Library/Frameworks/Python.framework/Versions/3.7/lib/python3.7/site-packages/telegram/vendor/ptb_urllib3/urllib3/connectionpool.py", line 695, in urlopen
    **response_kw)
  File "/Library/Frameworks/Python.framework/Versions/3.7/lib/python3.7/site-packages/telegram/vendor/ptb_urllib3/urllib3/connectionpool.py", line 695, in urlopen
    **response_kw)
  File "/Library/Frameworks/Python.framework/Versions/3.7/lib/python3.7/site-packages/telegram/vendor/ptb_urllib3/urllib3/connectionpool.py", line 666, in urlopen
    _stacktrace=sys.exc_info()[2])
  File "/Library/Frameworks/Python.framework/Versions/3.7/lib/python3.7/site-packages/telegram/vendor/ptb_urllib3/urllib3/util/retry.py", line 376, in increment
    raise MaxRetryError(_pool, url, error or ResponseError(cause))
telegram.vendor.ptb_urllib3.urllib3.exceptions.MaxRetryError: HTTPSConnectionPool(host='api.telegram.org', port=443): Max retries exceeded with url: /bot808049629:AAHXH6XLn_2HpMGsgUBn9y0TCI2mn22mJ8A/getUpdates (Caused by NewConnectionError('<telegram.vendor.ptb_urllib3.urllib3.connection.VerifiedHTTPSConnection object at 0x1109e9e10>: Failed to establish a new connection: [Errno 8] nodename nor servname provided, or not known'))

During handling of the above exception, another exception occurred:

Traceback (most recent call last):
  File "/Library/Frameworks/Python.framework/Versions/3.7/lib/python3.7/site-packages/telegram/ext/updater.py", line 332, in _network_loop_retry
    if not action_cb():
  File "/Library/Frameworks/Python.framework/Versions/3.7/lib/python3.7/site-packages/telegram/ext/updater.py", line 293, in polling_action_cb
    allowed_updates=allowed_updates)
  File "/Library/Frameworks/Python.framework/Versions/3.7/lib/python3.7/site-packages/telegram/bot.py", line 66, in decorator
    result = func(self, *args, **kwargs)
  File "/Library/Frameworks/Python.framework/Versions/3.7/lib/python3.7/site-packages/telegram/bot.py", line 1982, in get_updates
    result = self._request.post(url, data, timeout=float(read_latency) + float(timeout))
  File "/Library/Frameworks/Python.framework/Versions/3.7/lib/python3.7/site-packages/telegram/utils/request.py", line 327, in post
    **urlopen_kwargs)
  File "/Library/Frameworks/Python.framework/Versions/3.7/lib/python3.7/site-packages/telegram/utils/request.py", line 224, in _request_wrapper
    raise NetworkError('urllib3 HTTPError {0}'.format(error))
telegram.error.NetworkError: urllib3 HTTPError HTTPSConnectionPool(host='api.telegram.org', port=443): Max retries exceeded with url: /bot808049629:AAHXH6XLn_2HpMGsgUBn9y0TCI2mn22mJ8A/getUpdates (Caused by NewConnectionError('<telegram.vendor.ptb_urllib3.urllib3.connection.VerifiedHTTPSConnection object at 0x1109e9e10>: Failed to establish a new connection: [Errno 8] nodename nor servname provided, or not known'))
telegram.vendor.ptb_urllib3.urllib3.connectionpool - WARNING - Retrying (Retry(total=2, connect=None, read=None, redirect=None)) after connection broken by 'NewConnectionError('<telegram.vendor.ptb_urllib3.urllib3.connection.VerifiedHTTPSConnection object at 0x110901790>: Failed to establish a new connection: [Errno 8] nodename nor servname provided, or not known')': /bot808049629:AAHXH6XLn_2HpMGsgUBn9y0TCI2mn22mJ8A/getUpdates
telegram.vendor.ptb_urllib3.urllib3.connectionpool - WARNING - Retrying (Retry(total=1, connect=None, read=None, redirect=None)) after connection broken by 'NewConnectionError('<telegram.vendor.ptb_urllib3.urllib3.connection.VerifiedHTTPSConnection object at 0x110901250>: Failed to establish a new connection: [Errno 8] nodename nor servname provided, or not known')': /bot808049629:AAHXH6XLn_2HpMGsgUBn9y0TCI2mn22mJ8A/getUpdates
telegram.vendor.ptb_urllib3.urllib3.connectionpool - WARNING - Retrying (Retry(total=0, connect=None, read=None, redirect=None)) after connection broken by 'NewConnectionError('<telegram.vendor.ptb_urllib3.urllib3.connection.VerifiedHTTPSConnection object at 0x110901050>: Failed to establish a new connection: [Errno 8] nodename nor servname provided, or not known')': /bot808049629:AAHXH6XLn_2HpMGsgUBn9y0TCI2mn22mJ8A/getUpdates
telegram.ext.updater - ERROR - Error while getting Updates: urllib3 HTTPError HTTPSConnectionPool(host='api.telegram.org', port=443): Max retries exceeded with url: /bot808049629:AAHXH6XLn_2HpMGsgUBn9y0TCI2mn22mJ8A/getUpdates (Caused by NewConnectionError('<telegram.vendor.ptb_urllib3.urllib3.connection.VerifiedHTTPSConnection object at 0x11009c690>: Failed to establish a new connection: [Errno 8] nodename nor servname provided, or not known'))
telegram.ext.dispatcher - ERROR - No error handlers are registered, logging exception.
Traceback (most recent call last):
  File "/Library/Frameworks/Python.framework/Versions/3.7/lib/python3.7/site-packages/telegram/vendor/ptb_urllib3/urllib3/connection.py", line 141, in _new_conn
    (self.host, self.port), self.timeout, **extra_kw)
  File "/Library/Frameworks/Python.framework/Versions/3.7/lib/python3.7/site-packages/telegram/vendor/ptb_urllib3/urllib3/util/connection.py", line 60, in create_connection
    for res in socket.getaddrinfo(host, port, family, socket.SOCK_STREAM):
  File "/Library/Frameworks/Python.framework/Versions/3.7/lib/python3.7/socket.py", line 748, in getaddrinfo
    for res in _socket.getaddrinfo(host, port, family, type, proto, flags):
socket.gaierror: [Errno 8] nodename nor servname provided, or not known

During handling of the above exception, another exception occurred:

Traceback (most recent call last):
  File "/Library/Frameworks/Python.framework/Versions/3.7/lib/python3.7/site-packages/telegram/vendor/ptb_urllib3/urllib3/connectionpool.py", line 617, in urlopen
    chunked=chunked)
  File "/Library/Frameworks/Python.framework/Versions/3.7/lib/python3.7/site-packages/telegram/vendor/ptb_urllib3/urllib3/connectionpool.py", line 360, in _make_request
    self._validate_conn(conn)
  File "/Library/Frameworks/Python.framework/Versions/3.7/lib/python3.7/site-packages/telegram/vendor/ptb_urllib3/urllib3/connectionpool.py", line 857, in _validate_conn
    super(HTTPSConnectionPool, self)._validate_conn(conn)
  File "/Library/Frameworks/Python.framework/Versions/3.7/lib/python3.7/site-packages/telegram/vendor/ptb_urllib3/urllib3/connectionpool.py", line 289, in _validate_conn
    conn.connect()
  File "/Library/Frameworks/Python.framework/Versions/3.7/lib/python3.7/site-packages/telegram/vendor/ptb_urllib3/urllib3/connection.py", line 284, in connect
    conn = self._new_conn()
  File "/Library/Frameworks/Python.framework/Versions/3.7/lib/python3.7/site-packages/telegram/vendor/ptb_urllib3/urllib3/connection.py", line 150, in _new_conn
    self, "Failed to establish a new connection: %s" % e)
telegram.vendor.ptb_urllib3.urllib3.exceptions.NewConnectionError: <telegram.vendor.ptb_urllib3.urllib3.connection.VerifiedHTTPSConnection object at 0x11009c690>: Failed to establish a new connection: [Errno 8] nodename nor servname provided, or not known

During handling of the above exception, another exception occurred:

Traceback (most recent call last):
  File "/Library/Frameworks/Python.framework/Versions/3.7/lib/python3.7/site-packages/telegram/utils/request.py", line 218, in _request_wrapper
    resp = self._con_pool.request(*args, **kwargs)
  File "/Library/Frameworks/Python.framework/Versions/3.7/lib/python3.7/site-packages/telegram/vendor/ptb_urllib3/urllib3/request.py", line 70, in request
    **urlopen_kw)
  File "/Library/Frameworks/Python.framework/Versions/3.7/lib/python3.7/site-packages/telegram/vendor/ptb_urllib3/urllib3/request.py", line 148, in request_encode_body
    return self.urlopen(method, url, **extra_kw)
  File "/Library/Frameworks/Python.framework/Versions/3.7/lib/python3.7/site-packages/telegram/vendor/ptb_urllib3/urllib3/poolmanager.py", line 244, in urlopen
    response = conn.urlopen(method, u.request_uri, **kw)
  File "/Library/Frameworks/Python.framework/Versions/3.7/lib/python3.7/site-packages/telegram/vendor/ptb_urllib3/urllib3/connectionpool.py", line 695, in urlopen
    **response_kw)
  File "/Library/Frameworks/Python.framework/Versions/3.7/lib/python3.7/site-packages/telegram/vendor/ptb_urllib3/urllib3/connectionpool.py", line 695, in urlopen
    **response_kw)
  File "/Library/Frameworks/Python.framework/Versions/3.7/lib/python3.7/site-packages/telegram/vendor/ptb_urllib3/urllib3/connectionpool.py", line 695, in urlopen
    **response_kw)
  File "/Library/Frameworks/Python.framework/Versions/3.7/lib/python3.7/site-packages/telegram/vendor/ptb_urllib3/urllib3/connectionpool.py", line 666, in urlopen
    _stacktrace=sys.exc_info()[2])
  File "/Library/Frameworks/Python.framework/Versions/3.7/lib/python3.7/site-packages/telegram/vendor/ptb_urllib3/urllib3/util/retry.py", line 376, in increment
    raise MaxRetryError(_pool, url, error or ResponseError(cause))
telegram.vendor.ptb_urllib3.urllib3.exceptions.MaxRetryError: HTTPSConnectionPool(host='api.telegram.org', port=443): Max retries exceeded with url: /bot808049629:AAHXH6XLn_2HpMGsgUBn9y0TCI2mn22mJ8A/getUpdates (Caused by NewConnectionError('<telegram.vendor.ptb_urllib3.urllib3.connection.VerifiedHTTPSConnection object at 0x11009c690>: Failed to establish a new connection: [Errno 8] nodename nor servname provided, or not known'))

During handling of the above exception, another exception occurred:

Traceback (most recent call last):
  File "/Library/Frameworks/Python.framework/Versions/3.7/lib/python3.7/site-packages/telegram/ext/updater.py", line 332, in _network_loop_retry
    if not action_cb():
  File "/Library/Frameworks/Python.framework/Versions/3.7/lib/python3.7/site-packages/telegram/ext/updater.py", line 293, in polling_action_cb
    allowed_updates=allowed_updates)
  File "/Library/Frameworks/Python.framework/Versions/3.7/lib/python3.7/site-packages/telegram/bot.py", line 66, in decorator
    result = func(self, *args, **kwargs)
  File "/Library/Frameworks/Python.framework/Versions/3.7/lib/python3.7/site-packages/telegram/bot.py", line 1982, in get_updates
    result = self._request.post(url, data, timeout=float(read_latency) + float(timeout))
  File "/Library/Frameworks/Python.framework/Versions/3.7/lib/python3.7/site-packages/telegram/utils/request.py", line 327, in post
    **urlopen_kwargs)
  File "/Library/Frameworks/Python.framework/Versions/3.7/lib/python3.7/site-packages/telegram/utils/request.py", line 224, in _request_wrapper
    raise NetworkError('urllib3 HTTPError {0}'.format(error))
telegram.error.NetworkError: urllib3 HTTPError HTTPSConnectionPool(host='api.telegram.org', port=443): Max retries exceeded with url: /bot808049629:AAHXH6XLn_2HpMGsgUBn9y0TCI2mn22mJ8A/getUpdates (Caused by NewConnectionError('<telegram.vendor.ptb_urllib3.urllib3.connection.VerifiedHTTPSConnection object at 0x11009c690>: Failed to establish a new connection: [Errno 8] nodename nor servname provided, or not known'))
telegram.vendor.ptb_urllib3.urllib3.connectionpool - WARNING - Retrying (Retry(total=2, connect=None, read=None, redirect=None)) after connection broken by 'NewConnectionError('<telegram.vendor.ptb_urllib3.urllib3.connection.VerifiedHTTPSConnection object at 0x110789d50>: Failed to establish a new connection: [Errno 8] nodename nor servname provided, or not known')': /bot808049629:AAHXH6XLn_2HpMGsgUBn9y0TCI2mn22mJ8A/getUpdates
telegram.vendor.ptb_urllib3.urllib3.connectionpool - WARNING - Retrying (Retry(total=1, connect=None, read=None, redirect=None)) after connection broken by 'NewConnectionError('<telegram.vendor.ptb_urllib3.urllib3.connection.VerifiedHTTPSConnection object at 0x110789d90>: Failed to establish a new connection: [Errno 8] nodename nor servname provided, or not known')': /bot808049629:AAHXH6XLn_2HpMGsgUBn9y0TCI2mn22mJ8A/getUpdates
telegram.vendor.ptb_urllib3.urllib3.connectionpool - WARNING - Retrying (Retry(total=0, connect=None, read=None, redirect=None)) after connection broken by 'NewConnectionError('<telegram.vendor.ptb_urllib3.urllib3.connection.VerifiedHTTPSConnection object at 0x110789e10>: Failed to establish a new connection: [Errno 8] nodename nor servname provided, or not known')': /bot808049629:AAHXH6XLn_2HpMGsgUBn9y0TCI2mn22mJ8A/getUpdates
telegram.ext.updater - ERROR - Error while getting Updates: urllib3 HTTPError HTTPSConnectionPool(host='api.telegram.org', port=443): Max retries exceeded with url: /bot808049629:AAHXH6XLn_2HpMGsgUBn9y0TCI2mn22mJ8A/getUpdates (Caused by NewConnectionError('<telegram.vendor.ptb_urllib3.urllib3.connection.VerifiedHTTPSConnection object at 0x1109e9e90>: Failed to establish a new connection: [Errno 8] nodename nor servname provided, or not known'))
telegram.ext.dispatcher - ERROR - No error handlers are registered, logging exception.
Traceback (most recent call last):
  File "/Library/Frameworks/Python.framework/Versions/3.7/lib/python3.7/site-packages/telegram/vendor/ptb_urllib3/urllib3/connection.py", line 141, in _new_conn
    (self.host, self.port), self.timeout, **extra_kw)
  File "/Library/Frameworks/Python.framework/Versions/3.7/lib/python3.7/site-packages/telegram/vendor/ptb_urllib3/urllib3/util/connection.py", line 60, in create_connection
    for res in socket.getaddrinfo(host, port, family, socket.SOCK_STREAM):
  File "/Library/Frameworks/Python.framework/Versions/3.7/lib/python3.7/socket.py", line 748, in getaddrinfo
    for res in _socket.getaddrinfo(host, port, family, type, proto, flags):
socket.gaierror: [Errno 8] nodename nor servname provided, or not known

During handling of the above exception, another exception occurred:

Traceback (most recent call last):
  File "/Library/Frameworks/Python.framework/Versions/3.7/lib/python3.7/site-packages/telegram/vendor/ptb_urllib3/urllib3/connectionpool.py", line 617, in urlopen
    chunked=chunked)
  File "/Library/Frameworks/Python.framework/Versions/3.7/lib/python3.7/site-packages/telegram/vendor/ptb_urllib3/urllib3/connectionpool.py", line 360, in _make_request
    self._validate_conn(conn)
  File "/Library/Frameworks/Python.framework/Versions/3.7/lib/python3.7/site-packages/telegram/vendor/ptb_urllib3/urllib3/connectionpool.py", line 857, in _validate_conn
    super(HTTPSConnectionPool, self)._validate_conn(conn)
  File "/Library/Frameworks/Python.framework/Versions/3.7/lib/python3.7/site-packages/telegram/vendor/ptb_urllib3/urllib3/connectionpool.py", line 289, in _validate_conn
    conn.connect()
  File "/Library/Frameworks/Python.framework/Versions/3.7/lib/python3.7/site-packages/telegram/vendor/ptb_urllib3/urllib3/connection.py", line 284, in connect
    conn = self._new_conn()
  File "/Library/Frameworks/Python.framework/Versions/3.7/lib/python3.7/site-packages/telegram/vendor/ptb_urllib3/urllib3/connection.py", line 150, in _new_conn
    self, "Failed to establish a new connection: %s" % e)
telegram.vendor.ptb_urllib3.urllib3.exceptions.NewConnectionError: <telegram.vendor.ptb_urllib3.urllib3.connection.VerifiedHTTPSConnection object at 0x1109e9e90>: Failed to establish a new connection: [Errno 8] nodename nor servname provided, or not known

During handling of the above exception, another exception occurred:

Traceback (most recent call last):
  File "/Library/Frameworks/Python.framework/Versions/3.7/lib/python3.7/site-packages/telegram/utils/request.py", line 218, in _request_wrapper
    resp = self._con_pool.request(*args, **kwargs)
  File "/Library/Frameworks/Python.framework/Versions/3.7/lib/python3.7/site-packages/telegram/vendor/ptb_urllib3/urllib3/request.py", line 70, in request
    **urlopen_kw)
  File "/Library/Frameworks/Python.framework/Versions/3.7/lib/python3.7/site-packages/telegram/vendor/ptb_urllib3/urllib3/request.py", line 148, in request_encode_body
    return self.urlopen(method, url, **extra_kw)
  File "/Library/Frameworks/Python.framework/Versions/3.7/lib/python3.7/site-packages/telegram/vendor/ptb_urllib3/urllib3/poolmanager.py", line 244, in urlopen
    response = conn.urlopen(method, u.request_uri, **kw)
  File "/Library/Frameworks/Python.framework/Versions/3.7/lib/python3.7/site-packages/telegram/vendor/ptb_urllib3/urllib3/connectionpool.py", line 695, in urlopen
    **response_kw)
  File "/Library/Frameworks/Python.framework/Versions/3.7/lib/python3.7/site-packages/telegram/vendor/ptb_urllib3/urllib3/connectionpool.py", line 695, in urlopen
    **response_kw)
  File "/Library/Frameworks/Python.framework/Versions/3.7/lib/python3.7/site-packages/telegram/vendor/ptb_urllib3/urllib3/connectionpool.py", line 695, in urlopen
    **response_kw)
  File "/Library/Frameworks/Python.framework/Versions/3.7/lib/python3.7/site-packages/telegram/vendor/ptb_urllib3/urllib3/connectionpool.py", line 666, in urlopen
    _stacktrace=sys.exc_info()[2])
  File "/Library/Frameworks/Python.framework/Versions/3.7/lib/python3.7/site-packages/telegram/vendor/ptb_urllib3/urllib3/util/retry.py", line 376, in increment
    raise MaxRetryError(_pool, url, error or ResponseError(cause))
telegram.vendor.ptb_urllib3.urllib3.exceptions.MaxRetryError: HTTPSConnectionPool(host='api.telegram.org', port=443): Max retries exceeded with url: /bot808049629:AAHXH6XLn_2HpMGsgUBn9y0TCI2mn22mJ8A/getUpdates (Caused by NewConnectionError('<telegram.vendor.ptb_urllib3.urllib3.connection.VerifiedHTTPSConnection object at 0x1109e9e90>: Failed to establish a new connection: [Errno 8] nodename nor servname provided, or not known'))

During handling of the above exception, another exception occurred:

Traceback (most recent call last):
  File "/Library/Frameworks/Python.framework/Versions/3.7/lib/python3.7/site-packages/telegram/ext/updater.py", line 332, in _network_loop_retry
    if not action_cb():
  File "/Library/Frameworks/Python.framework/Versions/3.7/lib/python3.7/site-packages/telegram/ext/updater.py", line 293, in polling_action_cb
    allowed_updates=allowed_updates)
  File "/Library/Frameworks/Python.framework/Versions/3.7/lib/python3.7/site-packages/telegram/bot.py", line 66, in decorator
    result = func(self, *args, **kwargs)
  File "/Library/Frameworks/Python.framework/Versions/3.7/lib/python3.7/site-packages/telegram/bot.py", line 1982, in get_updates
    result = self._request.post(url, data, timeout=float(read_latency) + float(timeout))
  File "/Library/Frameworks/Python.framework/Versions/3.7/lib/python3.7/site-packages/telegram/utils/request.py", line 327, in post
    **urlopen_kwargs)
  File "/Library/Frameworks/Python.framework/Versions/3.7/lib/python3.7/site-packages/telegram/utils/request.py", line 224, in _request_wrapper
    raise NetworkError('urllib3 HTTPError {0}'.format(error))
telegram.error.NetworkError: urllib3 HTTPError HTTPSConnectionPool(host='api.telegram.org', port=443): Max retries exceeded with url: /bot808049629:AAHXH6XLn_2HpMGsgUBn9y0TCI2mn22mJ8A/getUpdates (Caused by NewConnectionError('<telegram.vendor.ptb_urllib3.urllib3.connection.VerifiedHTTPSConnection object at 0x1109e9e90>: Failed to establish a new connection: [Errno 8] nodename nor servname provided, or not known'))
telegram.vendor.ptb_urllib3.urllib3.connectionpool - WARNING - Retrying (Retry(total=2, connect=None, read=None, redirect=None)) after connection broken by 'NewConnectionError('<telegram.vendor.ptb_urllib3.urllib3.connection.VerifiedHTTPSConnection object at 0x110789e50>: Failed to establish a new connection: [Errno 8] nodename nor servname provided, or not known')': /bot808049629:AAHXH6XLn_2HpMGsgUBn9y0TCI2mn22mJ8A/getUpdates
telegram.vendor.ptb_urllib3.urllib3.connectionpool - WARNING - Retrying (Retry(total=1, connect=None, read=None, redirect=None)) after connection broken by 'NewConnectionError('<telegram.vendor.ptb_urllib3.urllib3.connection.VerifiedHTTPSConnection object at 0x1109ff0d0>: Failed to establish a new connection: [Errno 8] nodename nor servname provided, or not known')': /bot808049629:AAHXH6XLn_2HpMGsgUBn9y0TCI2mn22mJ8A/getUpdates
telegram.vendor.ptb_urllib3.urllib3.connectionpool - WARNING - Retrying (Retry(total=0, connect=None, read=None, redirect=None)) after connection broken by 'NewConnectionError('<telegram.vendor.ptb_urllib3.urllib3.connection.VerifiedHTTPSConnection object at 0x1109ff210>: Failed to establish a new connection: [Errno 8] nodename nor servname provided, or not known')': /bot808049629:AAHXH6XLn_2HpMGsgUBn9y0TCI2mn22mJ8A/getUpdates
telegram.ext.updater - ERROR - Error while getting Updates: urllib3 HTTPError HTTPSConnectionPool(host='api.telegram.org', port=443): Max retries exceeded with url: /bot808049629:AAHXH6XLn_2HpMGsgUBn9y0TCI2mn22mJ8A/getUpdates (Caused by NewConnectionError('<telegram.vendor.ptb_urllib3.urllib3.connection.VerifiedHTTPSConnection object at 0x1109ff350>: Failed to establish a new connection: [Errno 8] nodename nor servname provided, or not known'))
telegram.ext.dispatcher - ERROR - No error handlers are registered, logging exception.
Traceback (most recent call last):
  File "/Library/Frameworks/Python.framework/Versions/3.7/lib/python3.7/site-packages/telegram/vendor/ptb_urllib3/urllib3/connection.py", line 141, in _new_conn
    (self.host, self.port), self.timeout, **extra_kw)
  File "/Library/Frameworks/Python.framework/Versions/3.7/lib/python3.7/site-packages/telegram/vendor/ptb_urllib3/urllib3/util/connection.py", line 60, in create_connection
    for res in socket.getaddrinfo(host, port, family, socket.SOCK_STREAM):
  File "/Library/Frameworks/Python.framework/Versions/3.7/lib/python3.7/socket.py", line 748, in getaddrinfo
    for res in _socket.getaddrinfo(host, port, family, type, proto, flags):
socket.gaierror: [Errno 8] nodename nor servname provided, or not known

During handling of the above exception, another exception occurred:

Traceback (most recent call last):
  File "/Library/Frameworks/Python.framework/Versions/3.7/lib/python3.7/site-packages/telegram/vendor/ptb_urllib3/urllib3/connectionpool.py", line 617, in urlopen
    chunked=chunked)
  File "/Library/Frameworks/Python.framework/Versions/3.7/lib/python3.7/site-packages/telegram/vendor/ptb_urllib3/urllib3/connectionpool.py", line 360, in _make_request
    self._validate_conn(conn)
  File "/Library/Frameworks/Python.framework/Versions/3.7/lib/python3.7/site-packages/telegram/vendor/ptb_urllib3/urllib3/connectionpool.py", line 857, in _validate_conn
    super(HTTPSConnectionPool, self)._validate_conn(conn)
  File "/Library/Frameworks/Python.framework/Versions/3.7/lib/python3.7/site-packages/telegram/vendor/ptb_urllib3/urllib3/connectionpool.py", line 289, in _validate_conn
    conn.connect()
  File "/Library/Frameworks/Python.framework/Versions/3.7/lib/python3.7/site-packages/telegram/vendor/ptb_urllib3/urllib3/connection.py", line 284, in connect
    conn = self._new_conn()
  File "/Library/Frameworks/Python.framework/Versions/3.7/lib/python3.7/site-packages/telegram/vendor/ptb_urllib3/urllib3/connection.py", line 150, in _new_conn
    self, "Failed to establish a new connection: %s" % e)
telegram.vendor.ptb_urllib3.urllib3.exceptions.NewConnectionError: <telegram.vendor.ptb_urllib3.urllib3.connection.VerifiedHTTPSConnection object at 0x1109ff350>: Failed to establish a new connection: [Errno 8] nodename nor servname provided, or not known

During handling of the above exception, another exception occurred:

Traceback (most recent call last):
  File "/Library/Frameworks/Python.framework/Versions/3.7/lib/python3.7/site-packages/telegram/utils/request.py", line 218, in _request_wrapper
    resp = self._con_pool.request(*args, **kwargs)
  File "/Library/Frameworks/Python.framework/Versions/3.7/lib/python3.7/site-packages/telegram/vendor/ptb_urllib3/urllib3/request.py", line 70, in request
    **urlopen_kw)
  File "/Library/Frameworks/Python.framework/Versions/3.7/lib/python3.7/site-packages/telegram/vendor/ptb_urllib3/urllib3/request.py", line 148, in request_encode_body
    return self.urlopen(method, url, **extra_kw)
  File "/Library/Frameworks/Python.framework/Versions/3.7/lib/python3.7/site-packages/telegram/vendor/ptb_urllib3/urllib3/poolmanager.py", line 244, in urlopen
    response = conn.urlopen(method, u.request_uri, **kw)
  File "/Library/Frameworks/Python.framework/Versions/3.7/lib/python3.7/site-packages/telegram/vendor/ptb_urllib3/urllib3/connectionpool.py", line 695, in urlopen
    **response_kw)
  File "/Library/Frameworks/Python.framework/Versions/3.7/lib/python3.7/site-packages/telegram/vendor/ptb_urllib3/urllib3/connectionpool.py", line 695, in urlopen
    **response_kw)
  File "/Library/Frameworks/Python.framework/Versions/3.7/lib/python3.7/site-packages/telegram/vendor/ptb_urllib3/urllib3/connectionpool.py", line 695, in urlopen
    **response_kw)
  File "/Library/Frameworks/Python.framework/Versions/3.7/lib/python3.7/site-packages/telegram/vendor/ptb_urllib3/urllib3/connectionpool.py", line 666, in urlopen
    _stacktrace=sys.exc_info()[2])
  File "/Library/Frameworks/Python.framework/Versions/3.7/lib/python3.7/site-packages/telegram/vendor/ptb_urllib3/urllib3/util/retry.py", line 376, in increment
    raise MaxRetryError(_pool, url, error or ResponseError(cause))
telegram.vendor.ptb_urllib3.urllib3.exceptions.MaxRetryError: HTTPSConnectionPool(host='api.telegram.org', port=443): Max retries exceeded with url: /bot808049629:AAHXH6XLn_2HpMGsgUBn9y0TCI2mn22mJ8A/getUpdates (Caused by NewConnectionError('<telegram.vendor.ptb_urllib3.urllib3.connection.VerifiedHTTPSConnection object at 0x1109ff350>: Failed to establish a new connection: [Errno 8] nodename nor servname provided, or not known'))

During handling of the above exception, another exception occurred:

Traceback (most recent call last):
  File "/Library/Frameworks/Python.framework/Versions/3.7/lib/python3.7/site-packages/telegram/ext/updater.py", line 332, in _network_loop_retry
    if not action_cb():
  File "/Library/Frameworks/Python.framework/Versions/3.7/lib/python3.7/site-packages/telegram/ext/updater.py", line 293, in polling_action_cb
    allowed_updates=allowed_updates)
  File "/Library/Frameworks/Python.framework/Versions/3.7/lib/python3.7/site-packages/telegram/bot.py", line 66, in decorator
    result = func(self, *args, **kwargs)
  File "/Library/Frameworks/Python.framework/Versions/3.7/lib/python3.7/site-packages/telegram/bot.py", line 1982, in get_updates
    result = self._request.post(url, data, timeout=float(read_latency) + float(timeout))
  File "/Library/Frameworks/Python.framework/Versions/3.7/lib/python3.7/site-packages/telegram/utils/request.py", line 327, in post
    **urlopen_kwargs)
  File "/Library/Frameworks/Python.framework/Versions/3.7/lib/python3.7/site-packages/telegram/utils/request.py", line 224, in _request_wrapper
    raise NetworkError('urllib3 HTTPError {0}'.format(error))
telegram.error.NetworkError: urllib3 HTTPError HTTPSConnectionPool(host='api.telegram.org', port=443): Max retries exceeded with url: /bot808049629:AAHXH6XLn_2HpMGsgUBn9y0TCI2mn22mJ8A/getUpdates (Caused by NewConnectionError('<telegram.vendor.ptb_urllib3.urllib3.connection.VerifiedHTTPSConnection object at 0x1109ff350>: Failed to establish a new connection: [Errno 8] nodename nor servname provided, or not known'))
telegram.vendor.ptb_urllib3.urllib3.connectionpool - WARNING - Retrying (Retry(total=2, connect=None, read=None, redirect=None)) after connection broken by 'NewConnectionError('<telegram.vendor.ptb_urllib3.urllib3.connection.VerifiedHTTPSConnection object at 0x1109ff290>: Failed to establish a new connection: [Errno 8] nodename nor servname provided, or not known')': /bot808049629:AAHXH6XLn_2HpMGsgUBn9y0TCI2mn22mJ8A/getUpdates
telegram.vendor.ptb_urllib3.urllib3.connectionpool - WARNING - Retrying (Retry(total=1, connect=None, read=None, redirect=None)) after connection broken by 'NewConnectionError('<telegram.vendor.ptb_urllib3.urllib3.connection.VerifiedHTTPSConnection object at 0x1109ff390>: Failed to establish a new connection: [Errno 8] nodename nor servname provided, or not known')': /bot808049629:AAHXH6XLn_2HpMGsgUBn9y0TCI2mn22mJ8A/getUpdates
telegram.vendor.ptb_urllib3.urllib3.connectionpool - WARNING - Retrying (Retry(total=0, connect=None, read=None, redirect=None)) after connection broken by 'NewConnectionError('<telegram.vendor.ptb_urllib3.urllib3.connection.VerifiedHTTPSConnection object at 0x1109ff650>: Failed to establish a new connection: [Errno 8] nodename nor servname provided, or not known')': /bot808049629:AAHXH6XLn_2HpMGsgUBn9y0TCI2mn22mJ8A/getUpdates
telegram.ext.updater - ERROR - Error while getting Updates: urllib3 HTTPError HTTPSConnectionPool(host='api.telegram.org', port=443): Max retries exceeded with url: /bot808049629:AAHXH6XLn_2HpMGsgUBn9y0TCI2mn22mJ8A/getUpdates (Caused by NewConnectionError('<telegram.vendor.ptb_urllib3.urllib3.connection.VerifiedHTTPSConnection object at 0x1109ff7d0>: Failed to establish a new connection: [Errno 8] nodename nor servname provided, or not known'))
telegram.ext.dispatcher - ERROR - No error handlers are registered, logging exception.
Traceback (most recent call last):
  File "/Library/Frameworks/Python.framework/Versions/3.7/lib/python3.7/site-packages/telegram/vendor/ptb_urllib3/urllib3/connection.py", line 141, in _new_conn
    (self.host, self.port), self.timeout, **extra_kw)
  File "/Library/Frameworks/Python.framework/Versions/3.7/lib/python3.7/site-packages/telegram/vendor/ptb_urllib3/urllib3/util/connection.py", line 60, in create_connection
    for res in socket.getaddrinfo(host, port, family, socket.SOCK_STREAM):
  File "/Library/Frameworks/Python.framework/Versions/3.7/lib/python3.7/socket.py", line 748, in getaddrinfo
    for res in _socket.getaddrinfo(host, port, family, type, proto, flags):
socket.gaierror: [Errno 8] nodename nor servname provided, or not known

During handling of the above exception, another exception occurred:

Traceback (most recent call last):
  File "/Library/Frameworks/Python.framework/Versions/3.7/lib/python3.7/site-packages/telegram/vendor/ptb_urllib3/urllib3/connectionpool.py", line 617, in urlopen
    chunked=chunked)
  File "/Library/Frameworks/Python.framework/Versions/3.7/lib/python3.7/site-packages/telegram/vendor/ptb_urllib3/urllib3/connectionpool.py", line 360, in _make_request
    self._validate_conn(conn)
  File "/Library/Frameworks/Python.framework/Versions/3.7/lib/python3.7/site-packages/telegram/vendor/ptb_urllib3/urllib3/connectionpool.py", line 857, in _validate_conn
    super(HTTPSConnectionPool, self)._validate_conn(conn)
  File "/Library/Frameworks/Python.framework/Versions/3.7/lib/python3.7/site-packages/telegram/vendor/ptb_urllib3/urllib3/connectionpool.py", line 289, in _validate_conn
    conn.connect()
  File "/Library/Frameworks/Python.framework/Versions/3.7/lib/python3.7/site-packages/telegram/vendor/ptb_urllib3/urllib3/connection.py", line 284, in connect
    conn = self._new_conn()
  File "/Library/Frameworks/Python.framework/Versions/3.7/lib/python3.7/site-packages/telegram/vendor/ptb_urllib3/urllib3/connection.py", line 150, in _new_conn
    self, "Failed to establish a new connection: %s" % e)
telegram.vendor.ptb_urllib3.urllib3.exceptions.NewConnectionError: <telegram.vendor.ptb_urllib3.urllib3.connection.VerifiedHTTPSConnection object at 0x1109ff7d0>: Failed to establish a new connection: [Errno 8] nodename nor servname provided, or not known

During handling of the above exception, another exception occurred:

Traceback (most recent call last):
  File "/Library/Frameworks/Python.framework/Versions/3.7/lib/python3.7/site-packages/telegram/utils/request.py", line 218, in _request_wrapper
    resp = self._con_pool.request(*args, **kwargs)
  File "/Library/Frameworks/Python.framework/Versions/3.7/lib/python3.7/site-packages/telegram/vendor/ptb_urllib3/urllib3/request.py", line 70, in request
    **urlopen_kw)
  File "/Library/Frameworks/Python.framework/Versions/3.7/lib/python3.7/site-packages/telegram/vendor/ptb_urllib3/urllib3/request.py", line 148, in request_encode_body
    return self.urlopen(method, url, **extra_kw)
  File "/Library/Frameworks/Python.framework/Versions/3.7/lib/python3.7/site-packages/telegram/vendor/ptb_urllib3/urllib3/poolmanager.py", line 244, in urlopen
    response = conn.urlopen(method, u.request_uri, **kw)
  File "/Library/Frameworks/Python.framework/Versions/3.7/lib/python3.7/site-packages/telegram/vendor/ptb_urllib3/urllib3/connectionpool.py", line 695, in urlopen
    **response_kw)
  File "/Library/Frameworks/Python.framework/Versions/3.7/lib/python3.7/site-packages/telegram/vendor/ptb_urllib3/urllib3/connectionpool.py", line 695, in urlopen
    **response_kw)
  File "/Library/Frameworks/Python.framework/Versions/3.7/lib/python3.7/site-packages/telegram/vendor/ptb_urllib3/urllib3/connectionpool.py", line 695, in urlopen
    **response_kw)
  File "/Library/Frameworks/Python.framework/Versions/3.7/lib/python3.7/site-packages/telegram/vendor/ptb_urllib3/urllib3/connectionpool.py", line 666, in urlopen
    _stacktrace=sys.exc_info()[2])
  File "/Library/Frameworks/Python.framework/Versions/3.7/lib/python3.7/site-packages/telegram/vendor/ptb_urllib3/urllib3/util/retry.py", line 376, in increment
    raise MaxRetryError(_pool, url, error or ResponseError(cause))
telegram.vendor.ptb_urllib3.urllib3.exceptions.MaxRetryError: HTTPSConnectionPool(host='api.telegram.org', port=443): Max retries exceeded with url: /bot808049629:AAHXH6XLn_2HpMGsgUBn9y0TCI2mn22mJ8A/getUpdates (Caused by NewConnectionError('<telegram.vendor.ptb_urllib3.urllib3.connection.VerifiedHTTPSConnection object at 0x1109ff7d0>: Failed to establish a new connection: [Errno 8] nodename nor servname provided, or not known'))

During handling of the above exception, another exception occurred:

Traceback (most recent call last):
  File "/Library/Frameworks/Python.framework/Versions/3.7/lib/python3.7/site-packages/telegram/ext/updater.py", line 332, in _network_loop_retry
    if not action_cb():
  File "/Library/Frameworks/Python.framework/Versions/3.7/lib/python3.7/site-packages/telegram/ext/updater.py", line 293, in polling_action_cb
    allowed_updates=allowed_updates)
  File "/Library/Frameworks/Python.framework/Versions/3.7/lib/python3.7/site-packages/telegram/bot.py", line 66, in decorator
    result = func(self, *args, **kwargs)
  File "/Library/Frameworks/Python.framework/Versions/3.7/lib/python3.7/site-packages/telegram/bot.py", line 1982, in get_updates
    result = self._request.post(url, data, timeout=float(read_latency) + float(timeout))
  File "/Library/Frameworks/Python.framework/Versions/3.7/lib/python3.7/site-packages/telegram/utils/request.py", line 327, in post
    **urlopen_kwargs)
  File "/Library/Frameworks/Python.framework/Versions/3.7/lib/python3.7/site-packages/telegram/utils/request.py", line 224, in _request_wrapper
    raise NetworkError('urllib3 HTTPError {0}'.format(error))
telegram.error.NetworkError: urllib3 HTTPError HTTPSConnectionPool(host='api.telegram.org', port=443): Max retries exceeded with url: /bot808049629:AAHXH6XLn_2HpMGsgUBn9y0TCI2mn22mJ8A/getUpdates (Caused by NewConnectionError('<telegram.vendor.ptb_urllib3.urllib3.connection.VerifiedHTTPSConnection object at 0x1109ff7d0>: Failed to establish a new connection: [Errno 8] nodename nor servname provided, or not known'))
telegram.vendor.ptb_urllib3.urllib3.connectionpool - WARNING - Retrying (Retry(total=2, connect=None, read=None, redirect=None)) after connection broken by 'NewConnectionError('<telegram.vendor.ptb_urllib3.urllib3.connection.VerifiedHTTPSConnection object at 0x1109ff490>: Failed to establish a new connection: [Errno 8] nodename nor servname provided, or not known')': /bot808049629:AAHXH6XLn_2HpMGsgUBn9y0TCI2mn22mJ8A/getUpdates
telegram.vendor.ptb_urllib3.urllib3.connectionpool - WARNING - Retrying (Retry(total=1, connect=None, read=None, redirect=None)) after connection broken by 'NewConnectionError('<telegram.vendor.ptb_urllib3.urllib3.connection.VerifiedHTTPSConnection object at 0x1109ff810>: Failed to establish a new connection: [Errno 8] nodename nor servname provided, or not known')': /bot808049629:AAHXH6XLn_2HpMGsgUBn9y0TCI2mn22mJ8A/getUpdates
telegram.vendor.ptb_urllib3.urllib3.connectionpool - WARNING - Retrying (Retry(total=0, connect=None, read=None, redirect=None)) after connection broken by 'NewConnectionError('<telegram.vendor.ptb_urllib3.urllib3.connection.VerifiedHTTPSConnection object at 0x1109ffad0>: Failed to establish a new connection: [Errno 8] nodename nor servname provided, or not known')': /bot808049629:AAHXH6XLn_2HpMGsgUBn9y0TCI2mn22mJ8A/getUpdates
telegram.ext.updater - ERROR - Error while getting Updates: urllib3 HTTPError HTTPSConnectionPool(host='api.telegram.org', port=443): Max retries exceeded with url: /bot808049629:AAHXH6XLn_2HpMGsgUBn9y0TCI2mn22mJ8A/getUpdates (Caused by NewConnectionError('<telegram.vendor.ptb_urllib3.urllib3.connection.VerifiedHTTPSConnection object at 0x1109ffc50>: Failed to establish a new connection: [Errno 8] nodename nor servname provided, or not known'))
telegram.ext.dispatcher - ERROR - No error handlers are registered, logging exception.
Traceback (most recent call last):
  File "/Library/Frameworks/Python.framework/Versions/3.7/lib/python3.7/site-packages/telegram/vendor/ptb_urllib3/urllib3/connection.py", line 141, in _new_conn
    (self.host, self.port), self.timeout, **extra_kw)
  File "/Library/Frameworks/Python.framework/Versions/3.7/lib/python3.7/site-packages/telegram/vendor/ptb_urllib3/urllib3/util/connection.py", line 60, in create_connection
    for res in socket.getaddrinfo(host, port, family, socket.SOCK_STREAM):
  File "/Library/Frameworks/Python.framework/Versions/3.7/lib/python3.7/socket.py", line 748, in getaddrinfo
    for res in _socket.getaddrinfo(host, port, family, type, proto, flags):
socket.gaierror: [Errno 8] nodename nor servname provided, or not known

During handling of the above exception, another exception occurred:

Traceback (most recent call last):
  File "/Library/Frameworks/Python.framework/Versions/3.7/lib/python3.7/site-packages/telegram/vendor/ptb_urllib3/urllib3/connectionpool.py", line 617, in urlopen
    chunked=chunked)
  File "/Library/Frameworks/Python.framework/Versions/3.7/lib/python3.7/site-packages/telegram/vendor/ptb_urllib3/urllib3/connectionpool.py", line 360, in _make_request
    self._validate_conn(conn)
  File "/Library/Frameworks/Python.framework/Versions/3.7/lib/python3.7/site-packages/telegram/vendor/ptb_urllib3/urllib3/connectionpool.py", line 857, in _validate_conn
    super(HTTPSConnectionPool, self)._validate_conn(conn)
  File "/Library/Frameworks/Python.framework/Versions/3.7/lib/python3.7/site-packages/telegram/vendor/ptb_urllib3/urllib3/connectionpool.py", line 289, in _validate_conn
    conn.connect()
  File "/Library/Frameworks/Python.framework/Versions/3.7/lib/python3.7/site-packages/telegram/vendor/ptb_urllib3/urllib3/connection.py", line 284, in connect
    conn = self._new_conn()
  File "/Library/Frameworks/Python.framework/Versions/3.7/lib/python3.7/site-packages/telegram/vendor/ptb_urllib3/urllib3/connection.py", line 150, in _new_conn
    self, "Failed to establish a new connection: %s" % e)
telegram.vendor.ptb_urllib3.urllib3.exceptions.NewConnectionError: <telegram.vendor.ptb_urllib3.urllib3.connection.VerifiedHTTPSConnection object at 0x1109ffc50>: Failed to establish a new connection: [Errno 8] nodename nor servname provided, or not known

During handling of the above exception, another exception occurred:

Traceback (most recent call last):
  File "/Library/Frameworks/Python.framework/Versions/3.7/lib/python3.7/site-packages/telegram/utils/request.py", line 218, in _request_wrapper
    resp = self._con_pool.request(*args, **kwargs)
  File "/Library/Frameworks/Python.framework/Versions/3.7/lib/python3.7/site-packages/telegram/vendor/ptb_urllib3/urllib3/request.py", line 70, in request
    **urlopen_kw)
  File "/Library/Frameworks/Python.framework/Versions/3.7/lib/python3.7/site-packages/telegram/vendor/ptb_urllib3/urllib3/request.py", line 148, in request_encode_body
    return self.urlopen(method, url, **extra_kw)
  File "/Library/Frameworks/Python.framework/Versions/3.7/lib/python3.7/site-packages/telegram/vendor/ptb_urllib3/urllib3/poolmanager.py", line 244, in urlopen
    response = conn.urlopen(method, u.request_uri, **kw)
  File "/Library/Frameworks/Python.framework/Versions/3.7/lib/python3.7/site-packages/telegram/vendor/ptb_urllib3/urllib3/connectionpool.py", line 695, in urlopen
    **response_kw)
  File "/Library/Frameworks/Python.framework/Versions/3.7/lib/python3.7/site-packages/telegram/vendor/ptb_urllib3/urllib3/connectionpool.py", line 695, in urlopen
    **response_kw)
  File "/Library/Frameworks/Python.framework/Versions/3.7/lib/python3.7/site-packages/telegram/vendor/ptb_urllib3/urllib3/connectionpool.py", line 695, in urlopen
    **response_kw)
  File "/Library/Frameworks/Python.framework/Versions/3.7/lib/python3.7/site-packages/telegram/vendor/ptb_urllib3/urllib3/connectionpool.py", line 666, in urlopen
    _stacktrace=sys.exc_info()[2])
  File "/Library/Frameworks/Python.framework/Versions/3.7/lib/python3.7/site-packages/telegram/vendor/ptb_urllib3/urllib3/util/retry.py", line 376, in increment
    raise MaxRetryError(_pool, url, error or ResponseError(cause))
telegram.vendor.ptb_urllib3.urllib3.exceptions.MaxRetryError: HTTPSConnectionPool(host='api.telegram.org', port=443): Max retries exceeded with url: /bot808049629:AAHXH6XLn_2HpMGsgUBn9y0TCI2mn22mJ8A/getUpdates (Caused by NewConnectionError('<telegram.vendor.ptb_urllib3.urllib3.connection.VerifiedHTTPSConnection object at 0x1109ffc50>: Failed to establish a new connection: [Errno 8] nodename nor servname provided, or not known'))

During handling of the above exception, another exception occurred:

Traceback (most recent call last):
  File "/Library/Frameworks/Python.framework/Versions/3.7/lib/python3.7/site-packages/telegram/ext/updater.py", line 332, in _network_loop_retry
    if not action_cb():
  File "/Library/Frameworks/Python.framework/Versions/3.7/lib/python3.7/site-packages/telegram/ext/updater.py", line 293, in polling_action_cb
    allowed_updates=allowed_updates)
  File "/Library/Frameworks/Python.framework/Versions/3.7/lib/python3.7/site-packages/telegram/bot.py", line 66, in decorator
    result = func(self, *args, **kwargs)
  File "/Library/Frameworks/Python.framework/Versions/3.7/lib/python3.7/site-packages/telegram/bot.py", line 1982, in get_updates
    result = self._request.post(url, data, timeout=float(read_latency) + float(timeout))
  File "/Library/Frameworks/Python.framework/Versions/3.7/lib/python3.7/site-packages/telegram/utils/request.py", line 327, in post
    **urlopen_kwargs)
  File "/Library/Frameworks/Python.framework/Versions/3.7/lib/python3.7/site-packages/telegram/utils/request.py", line 224, in _request_wrapper
    raise NetworkError('urllib3 HTTPError {0}'.format(error))
telegram.error.NetworkError: urllib3 HTTPError HTTPSConnectionPool(host='api.telegram.org', port=443): Max retries exceeded with url: /bot808049629:AAHXH6XLn_2HpMGsgUBn9y0TCI2mn22mJ8A/getUpdates (Caused by NewConnectionError('<telegram.vendor.ptb_urllib3.urllib3.connection.VerifiedHTTPSConnection object at 0x1109ffc50>: Failed to establish a new connection: [Errno 8] nodename nor servname provided, or not known'))
telegram.vendor.ptb_urllib3.urllib3.connectionpool - WARNING - Retrying (Retry(total=2, connect=None, read=None, redirect=None)) after connection broken by 'NewConnectionError('<telegram.vendor.ptb_urllib3.urllib3.connection.VerifiedHTTPSConnection object at 0x1109ffd90>: Failed to establish a new connection: [Errno 8] nodename nor servname provided, or not known')': /bot808049629:AAHXH6XLn_2HpMGsgUBn9y0TCI2mn22mJ8A/getUpdates
telegram.vendor.ptb_urllib3.urllib3.connectionpool - WARNING - Retrying (Retry(total=1, connect=None, read=None, redirect=None)) after connection broken by 'NewConnectionError('<telegram.vendor.ptb_urllib3.urllib3.connection.VerifiedHTTPSConnection object at 0x1109ffc90>: Failed to establish a new connection: [Errno 8] nodename nor servname provided, or not known')': /bot808049629:AAHXH6XLn_2HpMGsgUBn9y0TCI2mn22mJ8A/getUpdates
telegram.vendor.ptb_urllib3.urllib3.connectionpool - WARNING - Retrying (Retry(total=0, connect=None, read=None, redirect=None)) after connection broken by 'NewConnectionError('<telegram.vendor.ptb_urllib3.urllib3.connection.VerifiedHTTPSConnection object at 0x1109fff50>: Failed to establish a new connection: [Errno 8] nodename nor servname provided, or not known')': /bot808049629:AAHXH6XLn_2HpMGsgUBn9y0TCI2mn22mJ8A/getUpdates
telegram.ext.updater - ERROR - Error while getting Updates: urllib3 HTTPError HTTPSConnectionPool(host='api.telegram.org', port=443): Max retries exceeded with url: /bot808049629:AAHXH6XLn_2HpMGsgUBn9y0TCI2mn22mJ8A/getUpdates (Caused by NewConnectionError('<telegram.vendor.ptb_urllib3.urllib3.connection.VerifiedHTTPSConnection object at 0x1109ff590>: Failed to establish a new connection: [Errno 8] nodename nor servname provided, or not known'))
telegram.ext.dispatcher - ERROR - No error handlers are registered, logging exception.
Traceback (most recent call last):
  File "/Library/Frameworks/Python.framework/Versions/3.7/lib/python3.7/site-packages/telegram/vendor/ptb_urllib3/urllib3/connection.py", line 141, in _new_conn
    (self.host, self.port), self.timeout, **extra_kw)
  File "/Library/Frameworks/Python.framework/Versions/3.7/lib/python3.7/site-packages/telegram/vendor/ptb_urllib3/urllib3/util/connection.py", line 60, in create_connection
    for res in socket.getaddrinfo(host, port, family, socket.SOCK_STREAM):
  File "/Library/Frameworks/Python.framework/Versions/3.7/lib/python3.7/socket.py", line 748, in getaddrinfo
    for res in _socket.getaddrinfo(host, port, family, type, proto, flags):
socket.gaierror: [Errno 8] nodename nor servname provided, or not known

During handling of the above exception, another exception occurred:

Traceback (most recent call last):
  File "/Library/Frameworks/Python.framework/Versions/3.7/lib/python3.7/site-packages/telegram/vendor/ptb_urllib3/urllib3/connectionpool.py", line 617, in urlopen
    chunked=chunked)
  File "/Library/Frameworks/Python.framework/Versions/3.7/lib/python3.7/site-packages/telegram/vendor/ptb_urllib3/urllib3/connectionpool.py", line 360, in _make_request
    self._validate_conn(conn)
  File "/Library/Frameworks/Python.framework/Versions/3.7/lib/python3.7/site-packages/telegram/vendor/ptb_urllib3/urllib3/connectionpool.py", line 857, in _validate_conn
    super(HTTPSConnectionPool, self)._validate_conn(conn)
  File "/Library/Frameworks/Python.framework/Versions/3.7/lib/python3.7/site-packages/telegram/vendor/ptb_urllib3/urllib3/connectionpool.py", line 289, in _validate_conn
    conn.connect()
  File "/Library/Frameworks/Python.framework/Versions/3.7/lib/python3.7/site-packages/telegram/vendor/ptb_urllib3/urllib3/connection.py", line 284, in connect
    conn = self._new_conn()
  File "/Library/Frameworks/Python.framework/Versions/3.7/lib/python3.7/site-packages/telegram/vendor/ptb_urllib3/urllib3/connection.py", line 150, in _new_conn
    self, "Failed to establish a new connection: %s" % e)
telegram.vendor.ptb_urllib3.urllib3.exceptions.NewConnectionError: <telegram.vendor.ptb_urllib3.urllib3.connection.VerifiedHTTPSConnection object at 0x1109ff590>: Failed to establish a new connection: [Errno 8] nodename nor servname provided, or not known

During handling of the above exception, another exception occurred:

Traceback (most recent call last):
  File "/Library/Frameworks/Python.framework/Versions/3.7/lib/python3.7/site-packages/telegram/utils/request.py", line 218, in _request_wrapper
    resp = self._con_pool.request(*args, **kwargs)
  File "/Library/Frameworks/Python.framework/Versions/3.7/lib/python3.7/site-packages/telegram/vendor/ptb_urllib3/urllib3/request.py", line 70, in request
    **urlopen_kw)
  File "/Library/Frameworks/Python.framework/Versions/3.7/lib/python3.7/site-packages/telegram/vendor/ptb_urllib3/urllib3/request.py", line 148, in request_encode_body
    return self.urlopen(method, url, **extra_kw)
  File "/Library/Frameworks/Python.framework/Versions/3.7/lib/python3.7/site-packages/telegram/vendor/ptb_urllib3/urllib3/poolmanager.py", line 244, in urlopen
    response = conn.urlopen(method, u.request_uri, **kw)
  File "/Library/Frameworks/Python.framework/Versions/3.7/lib/python3.7/site-packages/telegram/vendor/ptb_urllib3/urllib3/connectionpool.py", line 695, in urlopen
    **response_kw)
  File "/Library/Frameworks/Python.framework/Versions/3.7/lib/python3.7/site-packages/telegram/vendor/ptb_urllib3/urllib3/connectionpool.py", line 695, in urlopen
    **response_kw)
  File "/Library/Frameworks/Python.framework/Versions/3.7/lib/python3.7/site-packages/telegram/vendor/ptb_urllib3/urllib3/connectionpool.py", line 695, in urlopen
    **response_kw)
  File "/Library/Frameworks/Python.framework/Versions/3.7/lib/python3.7/site-packages/telegram/vendor/ptb_urllib3/urllib3/connectionpool.py", line 666, in urlopen
    _stacktrace=sys.exc_info()[2])
  File "/Library/Frameworks/Python.framework/Versions/3.7/lib/python3.7/site-packages/telegram/vendor/ptb_urllib3/urllib3/util/retry.py", line 376, in increment
    raise MaxRetryError(_pool, url, error or ResponseError(cause))
telegram.vendor.ptb_urllib3.urllib3.exceptions.MaxRetryError: HTTPSConnectionPool(host='api.telegram.org', port=443): Max retries exceeded with url: /bot808049629:AAHXH6XLn_2HpMGsgUBn9y0TCI2mn22mJ8A/getUpdates (Caused by NewConnectionError('<telegram.vendor.ptb_urllib3.urllib3.connection.VerifiedHTTPSConnection object at 0x1109ff590>: Failed to establish a new connection: [Errno 8] nodename nor servname provided, or not known'))

During handling of the above exception, another exception occurred:

Traceback (most recent call last):
  File "/Library/Frameworks/Python.framework/Versions/3.7/lib/python3.7/site-packages/telegram/ext/updater.py", line 332, in _network_loop_retry
    if not action_cb():
  File "/Library/Frameworks/Python.framework/Versions/3.7/lib/python3.7/site-packages/telegram/ext/updater.py", line 293, in polling_action_cb
    allowed_updates=allowed_updates)
  File "/Library/Frameworks/Python.framework/Versions/3.7/lib/python3.7/site-packages/telegram/bot.py", line 66, in decorator
    result = func(self, *args, **kwargs)
  File "/Library/Frameworks/Python.framework/Versions/3.7/lib/python3.7/site-packages/telegram/bot.py", line 1982, in get_updates
    result = self._request.post(url, data, timeout=float(read_latency) + float(timeout))
  File "/Library/Frameworks/Python.framework/Versions/3.7/lib/python3.7/site-packages/telegram/utils/request.py", line 327, in post
    **urlopen_kwargs)
  File "/Library/Frameworks/Python.framework/Versions/3.7/lib/python3.7/site-packages/telegram/utils/request.py", line 224, in _request_wrapper
    raise NetworkError('urllib3 HTTPError {0}'.format(error))
telegram.error.NetworkError: urllib3 HTTPError HTTPSConnectionPool(host='api.telegram.org', port=443): Max retries exceeded with url: /bot808049629:AAHXH6XLn_2HpMGsgUBn9y0TCI2mn22mJ8A/getUpdates (Caused by NewConnectionError('<telegram.vendor.ptb_urllib3.urllib3.connection.VerifiedHTTPSConnection object at 0x1109ff590>: Failed to establish a new connection: [Errno 8] nodename nor servname provided, or not known'))
telegram.vendor.ptb_urllib3.urllib3.connectionpool - WARNING - Retrying (Retry(total=2, connect=None, read=None, redirect=None)) after connection broken by 'NewConnectionError('<telegram.vendor.ptb_urllib3.urllib3.connection.VerifiedHTTPSConnection object at 0x1109ffe10>: Failed to establish a new connection: [Errno 8] nodename nor servname provided, or not known')': /bot808049629:AAHXH6XLn_2HpMGsgUBn9y0TCI2mn22mJ8A/getUpdates
telegram.vendor.ptb_urllib3.urllib3.connectionpool - WARNING - Retrying (Retry(total=1, connect=None, read=None, redirect=None)) after connection broken by 'NewConnectionError('<telegram.vendor.ptb_urllib3.urllib3.connection.VerifiedHTTPSConnection object at 0x1109ff690>: Failed to establish a new connection: [Errno 8] nodename nor servname provided, or not known')': /bot808049629:AAHXH6XLn_2HpMGsgUBn9y0TCI2mn22mJ8A/getUpdates
telegram.vendor.ptb_urllib3.urllib3.connectionpool - WARNING - Retrying (Retry(total=0, connect=None, read=None, redirect=None)) after connection broken by 'NewConnectionError('<telegram.vendor.ptb_urllib3.urllib3.connection.VerifiedHTTPSConnection object at 0x1109ff190>: Failed to establish a new connection: [Errno 8] nodename nor servname provided, or not known')': /bot808049629:AAHXH6XLn_2HpMGsgUBn9y0TCI2mn22mJ8A/getUpdates
telegram.ext.updater - ERROR - Error while getting Updates: urllib3 HTTPError HTTPSConnectionPool(host='api.telegram.org', port=443): Max retries exceeded with url: /bot808049629:AAHXH6XLn_2HpMGsgUBn9y0TCI2mn22mJ8A/getUpdates (Caused by NewConnectionError('<telegram.vendor.ptb_urllib3.urllib3.connection.VerifiedHTTPSConnection object at 0x1106cbe90>: Failed to establish a new connection: [Errno 8] nodename nor servname provided, or not known'))
telegram.ext.dispatcher - ERROR - No error handlers are registered, logging exception.
Traceback (most recent call last):
  File "/Library/Frameworks/Python.framework/Versions/3.7/lib/python3.7/site-packages/telegram/vendor/ptb_urllib3/urllib3/connection.py", line 141, in _new_conn
    (self.host, self.port), self.timeout, **extra_kw)
  File "/Library/Frameworks/Python.framework/Versions/3.7/lib/python3.7/site-packages/telegram/vendor/ptb_urllib3/urllib3/util/connection.py", line 60, in create_connection
    for res in socket.getaddrinfo(host, port, family, socket.SOCK_STREAM):
  File "/Library/Frameworks/Python.framework/Versions/3.7/lib/python3.7/socket.py", line 748, in getaddrinfo
    for res in _socket.getaddrinfo(host, port, family, type, proto, flags):
socket.gaierror: [Errno 8] nodename nor servname provided, or not known

During handling of the above exception, another exception occurred:

Traceback (most recent call last):
  File "/Library/Frameworks/Python.framework/Versions/3.7/lib/python3.7/site-packages/telegram/vendor/ptb_urllib3/urllib3/connectionpool.py", line 617, in urlopen
    chunked=chunked)
  File "/Library/Frameworks/Python.framework/Versions/3.7/lib/python3.7/site-packages/telegram/vendor/ptb_urllib3/urllib3/connectionpool.py", line 360, in _make_request
    self._validate_conn(conn)
  File "/Library/Frameworks/Python.framework/Versions/3.7/lib/python3.7/site-packages/telegram/vendor/ptb_urllib3/urllib3/connectionpool.py", line 857, in _validate_conn
    super(HTTPSConnectionPool, self)._validate_conn(conn)
  File "/Library/Frameworks/Python.framework/Versions/3.7/lib/python3.7/site-packages/telegram/vendor/ptb_urllib3/urllib3/connectionpool.py", line 289, in _validate_conn
    conn.connect()
  File "/Library/Frameworks/Python.framework/Versions/3.7/lib/python3.7/site-packages/telegram/vendor/ptb_urllib3/urllib3/connection.py", line 284, in connect
    conn = self._new_conn()
  File "/Library/Frameworks/Python.framework/Versions/3.7/lib/python3.7/site-packages/telegram/vendor/ptb_urllib3/urllib3/connection.py", line 150, in _new_conn
    self, "Failed to establish a new connection: %s" % e)
telegram.vendor.ptb_urllib3.urllib3.exceptions.NewConnectionError: <telegram.vendor.ptb_urllib3.urllib3.connection.VerifiedHTTPSConnection object at 0x1106cbe90>: Failed to establish a new connection: [Errno 8] nodename nor servname provided, or not known

During handling of the above exception, another exception occurred:

Traceback (most recent call last):
  File "/Library/Frameworks/Python.framework/Versions/3.7/lib/python3.7/site-packages/telegram/utils/request.py", line 218, in _request_wrapper
    resp = self._con_pool.request(*args, **kwargs)
  File "/Library/Frameworks/Python.framework/Versions/3.7/lib/python3.7/site-packages/telegram/vendor/ptb_urllib3/urllib3/request.py", line 70, in request
    **urlopen_kw)
  File "/Library/Frameworks/Python.framework/Versions/3.7/lib/python3.7/site-packages/telegram/vendor/ptb_urllib3/urllib3/request.py", line 148, in request_encode_body
    return self.urlopen(method, url, **extra_kw)
  File "/Library/Frameworks/Python.framework/Versions/3.7/lib/python3.7/site-packages/telegram/vendor/ptb_urllib3/urllib3/poolmanager.py", line 244, in urlopen
    response = conn.urlopen(method, u.request_uri, **kw)
  File "/Library/Frameworks/Python.framework/Versions/3.7/lib/python3.7/site-packages/telegram/vendor/ptb_urllib3/urllib3/connectionpool.py", line 695, in urlopen
    **response_kw)
  File "/Library/Frameworks/Python.framework/Versions/3.7/lib/python3.7/site-packages/telegram/vendor/ptb_urllib3/urllib3/connectionpool.py", line 695, in urlopen
    **response_kw)
  File "/Library/Frameworks/Python.framework/Versions/3.7/lib/python3.7/site-packages/telegram/vendor/ptb_urllib3/urllib3/connectionpool.py", line 695, in urlopen
    **response_kw)
  File "/Library/Frameworks/Python.framework/Versions/3.7/lib/python3.7/site-packages/telegram/vendor/ptb_urllib3/urllib3/connectionpool.py", line 666, in urlopen
    _stacktrace=sys.exc_info()[2])
  File "/Library/Frameworks/Python.framework/Versions/3.7/lib/python3.7/site-packages/telegram/vendor/ptb_urllib3/urllib3/util/retry.py", line 376, in increment
    raise MaxRetryError(_pool, url, error or ResponseError(cause))
telegram.vendor.ptb_urllib3.urllib3.exceptions.MaxRetryError: HTTPSConnectionPool(host='api.telegram.org', port=443): Max retries exceeded with url: /bot808049629:AAHXH6XLn_2HpMGsgUBn9y0TCI2mn22mJ8A/getUpdates (Caused by NewConnectionError('<telegram.vendor.ptb_urllib3.urllib3.connection.VerifiedHTTPSConnection object at 0x1106cbe90>: Failed to establish a new connection: [Errno 8] nodename nor servname provided, or not known'))

During handling of the above exception, another exception occurred:

Traceback (most recent call last):
  File "/Library/Frameworks/Python.framework/Versions/3.7/lib/python3.7/site-packages/telegram/ext/updater.py", line 332, in _network_loop_retry
    if not action_cb():
  File "/Library/Frameworks/Python.framework/Versions/3.7/lib/python3.7/site-packages/telegram/ext/updater.py", line 293, in polling_action_cb
    allowed_updates=allowed_updates)
  File "/Library/Frameworks/Python.framework/Versions/3.7/lib/python3.7/site-packages/telegram/bot.py", line 66, in decorator
    result = func(self, *args, **kwargs)
  File "/Library/Frameworks/Python.framework/Versions/3.7/lib/python3.7/site-packages/telegram/bot.py", line 1982, in get_updates
    result = self._request.post(url, data, timeout=float(read_latency) + float(timeout))
  File "/Library/Frameworks/Python.framework/Versions/3.7/lib/python3.7/site-packages/telegram/utils/request.py", line 327, in post
    **urlopen_kwargs)
  File "/Library/Frameworks/Python.framework/Versions/3.7/lib/python3.7/site-packages/telegram/utils/request.py", line 224, in _request_wrapper
    raise NetworkError('urllib3 HTTPError {0}'.format(error))
telegram.error.NetworkError: urllib3 HTTPError HTTPSConnectionPool(host='api.telegram.org', port=443): Max retries exceeded with url: /bot808049629:AAHXH6XLn_2HpMGsgUBn9y0TCI2mn22mJ8A/getUpdates (Caused by NewConnectionError('<telegram.vendor.ptb_urllib3.urllib3.connection.VerifiedHTTPSConnection object at 0x1106cbe90>: Failed to establish a new connection: [Errno 8] nodename nor servname provided, or not known'))
telegram.vendor.ptb_urllib3.urllib3.connectionpool - WARNING - Retrying (Retry(total=2, connect=None, read=None, redirect=None)) after connection broken by 'NewConnectionError('<telegram.vendor.ptb_urllib3.urllib3.connection.VerifiedHTTPSConnection object at 0x1109ff390>: Failed to establish a new connection: [Errno 8] nodename nor servname provided, or not known')': /bot808049629:AAHXH6XLn_2HpMGsgUBn9y0TCI2mn22mJ8A/getUpdates
telegram.vendor.ptb_urllib3.urllib3.connectionpool - WARNING - Retrying (Retry(total=1, connect=None, read=None, redirect=None)) after connection broken by 'NewConnectionError('<telegram.vendor.ptb_urllib3.urllib3.connection.VerifiedHTTPSConnection object at 0x1109e9f10>: Failed to establish a new connection: [Errno 8] nodename nor servname provided, or not known')': /bot808049629:AAHXH6XLn_2HpMGsgUBn9y0TCI2mn22mJ8A/getUpdates
telegram.vendor.ptb_urllib3.urllib3.connectionpool - WARNING - Retrying (Retry(total=0, connect=None, read=None, redirect=None)) after connection broken by 'NewConnectionError('<telegram.vendor.ptb_urllib3.urllib3.connection.VerifiedHTTPSConnection object at 0x1106d9190>: Failed to establish a new connection: [Errno 8] nodename nor servname provided, or not known')': /bot808049629:AAHXH6XLn_2HpMGsgUBn9y0TCI2mn22mJ8A/getUpdates
telegram.ext.updater - ERROR - Error while getting Updates: urllib3 HTTPError HTTPSConnectionPool(host='api.telegram.org', port=443): Max retries exceeded with url: /bot808049629:AAHXH6XLn_2HpMGsgUBn9y0TCI2mn22mJ8A/getUpdates (Caused by NewConnectionError('<telegram.vendor.ptb_urllib3.urllib3.connection.VerifiedHTTPSConnection object at 0x110789e90>: Failed to establish a new connection: [Errno 8] nodename nor servname provided, or not known'))
telegram.ext.dispatcher - ERROR - No error handlers are registered, logging exception.
Traceback (most recent call last):
  File "/Library/Frameworks/Python.framework/Versions/3.7/lib/python3.7/site-packages/telegram/vendor/ptb_urllib3/urllib3/connection.py", line 141, in _new_conn
    (self.host, self.port), self.timeout, **extra_kw)
  File "/Library/Frameworks/Python.framework/Versions/3.7/lib/python3.7/site-packages/telegram/vendor/ptb_urllib3/urllib3/util/connection.py", line 60, in create_connection
    for res in socket.getaddrinfo(host, port, family, socket.SOCK_STREAM):
  File "/Library/Frameworks/Python.framework/Versions/3.7/lib/python3.7/socket.py", line 748, in getaddrinfo
    for res in _socket.getaddrinfo(host, port, family, type, proto, flags):
socket.gaierror: [Errno 8] nodename nor servname provided, or not known

During handling of the above exception, another exception occurred:

Traceback (most recent call last):
  File "/Library/Frameworks/Python.framework/Versions/3.7/lib/python3.7/site-packages/telegram/vendor/ptb_urllib3/urllib3/connectionpool.py", line 617, in urlopen
    chunked=chunked)
  File "/Library/Frameworks/Python.framework/Versions/3.7/lib/python3.7/site-packages/telegram/vendor/ptb_urllib3/urllib3/connectionpool.py", line 360, in _make_request
    self._validate_conn(conn)
  File "/Library/Frameworks/Python.framework/Versions/3.7/lib/python3.7/site-packages/telegram/vendor/ptb_urllib3/urllib3/connectionpool.py", line 857, in _validate_conn
    super(HTTPSConnectionPool, self)._validate_conn(conn)
  File "/Library/Frameworks/Python.framework/Versions/3.7/lib/python3.7/site-packages/telegram/vendor/ptb_urllib3/urllib3/connectionpool.py", line 289, in _validate_conn
    conn.connect()
  File "/Library/Frameworks/Python.framework/Versions/3.7/lib/python3.7/site-packages/telegram/vendor/ptb_urllib3/urllib3/connection.py", line 284, in connect
    conn = self._new_conn()
  File "/Library/Frameworks/Python.framework/Versions/3.7/lib/python3.7/site-packages/telegram/vendor/ptb_urllib3/urllib3/connection.py", line 150, in _new_conn
    self, "Failed to establish a new connection: %s" % e)
telegram.vendor.ptb_urllib3.urllib3.exceptions.NewConnectionError: <telegram.vendor.ptb_urllib3.urllib3.connection.VerifiedHTTPSConnection object at 0x110789e90>: Failed to establish a new connection: [Errno 8] nodename nor servname provided, or not known

During handling of the above exception, another exception occurred:

Traceback (most recent call last):
  File "/Library/Frameworks/Python.framework/Versions/3.7/lib/python3.7/site-packages/telegram/utils/request.py", line 218, in _request_wrapper
    resp = self._con_pool.request(*args, **kwargs)
  File "/Library/Frameworks/Python.framework/Versions/3.7/lib/python3.7/site-packages/telegram/vendor/ptb_urllib3/urllib3/request.py", line 70, in request
    **urlopen_kw)
  File "/Library/Frameworks/Python.framework/Versions/3.7/lib/python3.7/site-packages/telegram/vendor/ptb_urllib3/urllib3/request.py", line 148, in request_encode_body
    return self.urlopen(method, url, **extra_kw)
  File "/Library/Frameworks/Python.framework/Versions/3.7/lib/python3.7/site-packages/telegram/vendor/ptb_urllib3/urllib3/poolmanager.py", line 244, in urlopen
    response = conn.urlopen(method, u.request_uri, **kw)
  File "/Library/Frameworks/Python.framework/Versions/3.7/lib/python3.7/site-packages/telegram/vendor/ptb_urllib3/urllib3/connectionpool.py", line 695, in urlopen
    **response_kw)
  File "/Library/Frameworks/Python.framework/Versions/3.7/lib/python3.7/site-packages/telegram/vendor/ptb_urllib3/urllib3/connectionpool.py", line 695, in urlopen
    **response_kw)
  File "/Library/Frameworks/Python.framework/Versions/3.7/lib/python3.7/site-packages/telegram/vendor/ptb_urllib3/urllib3/connectionpool.py", line 695, in urlopen
    **response_kw)
  File "/Library/Frameworks/Python.framework/Versions/3.7/lib/python3.7/site-packages/telegram/vendor/ptb_urllib3/urllib3/connectionpool.py", line 666, in urlopen
    _stacktrace=sys.exc_info()[2])
  File "/Library/Frameworks/Python.framework/Versions/3.7/lib/python3.7/site-packages/telegram/vendor/ptb_urllib3/urllib3/util/retry.py", line 376, in increment
    raise MaxRetryError(_pool, url, error or ResponseError(cause))
telegram.vendor.ptb_urllib3.urllib3.exceptions.MaxRetryError: HTTPSConnectionPool(host='api.telegram.org', port=443): Max retries exceeded with url: /bot808049629:AAHXH6XLn_2HpMGsgUBn9y0TCI2mn22mJ8A/getUpdates (Caused by NewConnectionError('<telegram.vendor.ptb_urllib3.urllib3.connection.VerifiedHTTPSConnection object at 0x110789e90>: Failed to establish a new connection: [Errno 8] nodename nor servname provided, or not known'))

During handling of the above exception, another exception occurred:

Traceback (most recent call last):
  File "/Library/Frameworks/Python.framework/Versions/3.7/lib/python3.7/site-packages/telegram/ext/updater.py", line 332, in _network_loop_retry
    if not action_cb():
  File "/Library/Frameworks/Python.framework/Versions/3.7/lib/python3.7/site-packages/telegram/ext/updater.py", line 293, in polling_action_cb
    allowed_updates=allowed_updates)
  File "/Library/Frameworks/Python.framework/Versions/3.7/lib/python3.7/site-packages/telegram/bot.py", line 66, in decorator
    result = func(self, *args, **kwargs)
  File "/Library/Frameworks/Python.framework/Versions/3.7/lib/python3.7/site-packages/telegram/bot.py", line 1982, in get_updates
    result = self._request.post(url, data, timeout=float(read_latency) + float(timeout))
  File "/Library/Frameworks/Python.framework/Versions/3.7/lib/python3.7/site-packages/telegram/utils/request.py", line 327, in post
    **urlopen_kwargs)
  File "/Library/Frameworks/Python.framework/Versions/3.7/lib/python3.7/site-packages/telegram/utils/request.py", line 224, in _request_wrapper
    raise NetworkError('urllib3 HTTPError {0}'.format(error))
telegram.error.NetworkError: urllib3 HTTPError HTTPSConnectionPool(host='api.telegram.org', port=443): Max retries exceeded with url: /bot808049629:AAHXH6XLn_2HpMGsgUBn9y0TCI2mn22mJ8A/getUpdates (Caused by NewConnectionError('<telegram.vendor.ptb_urllib3.urllib3.connection.VerifiedHTTPSConnection object at 0x110789e90>: Failed to establish a new connection: [Errno 8] nodename nor servname provided, or not known'))
telegram.vendor.ptb_urllib3.urllib3.connectionpool - WARNING - Retrying (Retry(total=2, connect=None, read=None, redirect=None)) after connection broken by 'ConnectTimeoutError(<telegram.vendor.ptb_urllib3.urllib3.connection.VerifiedHTTPSConnection object at 0x110789c50>, 'Connection to api.telegram.org timed out. (connect timeout=5.0)')': /bot808049629:AAHXH6XLn_2HpMGsgUBn9y0TCI2mn22mJ8A/getUpdates
telegram.vendor.ptb_urllib3.urllib3.connectionpool - WARNING - Retrying (Retry(total=1, connect=None, read=None, redirect=None)) after connection broken by 'ConnectTimeoutError(<telegram.vendor.ptb_urllib3.urllib3.connection.VerifiedHTTPSConnection object at 0x1109014d0>, 'Connection to api.telegram.org timed out. (connect timeout=5.0)')': /bot808049629:AAHXH6XLn_2HpMGsgUBn9y0TCI2mn22mJ8A/getUpdates
telegram.vendor.ptb_urllib3.urllib3.connectionpool - WARNING - Retrying (Retry(total=0, connect=None, read=None, redirect=None)) after connection broken by 'ConnectTimeoutError(<telegram.vendor.ptb_urllib3.urllib3.connection.VerifiedHTTPSConnection object at 0x110901dd0>, 'Connection to api.telegram.org timed out. (connect timeout=5.0)')': /bot808049629:AAHXH6XLn_2HpMGsgUBn9y0TCI2mn22mJ8A/getUpdates
telegram.ext.updater - ERROR - Error while getting Updates: urllib3 HTTPError HTTPSConnectionPool(host='api.telegram.org', port=443): Max retries exceeded with url: /bot808049629:AAHXH6XLn_2HpMGsgUBn9y0TCI2mn22mJ8A/getUpdates (Caused by NewConnectionError('<telegram.vendor.ptb_urllib3.urllib3.connection.VerifiedHTTPSConnection object at 0x1109011d0>: Failed to establish a new connection: [Errno 8] nodename nor servname provided, or not known'))
telegram.ext.dispatcher - ERROR - No error handlers are registered, logging exception.
Traceback (most recent call last):
  File "/Library/Frameworks/Python.framework/Versions/3.7/lib/python3.7/site-packages/telegram/vendor/ptb_urllib3/urllib3/connection.py", line 141, in _new_conn
    (self.host, self.port), self.timeout, **extra_kw)
  File "/Library/Frameworks/Python.framework/Versions/3.7/lib/python3.7/site-packages/telegram/vendor/ptb_urllib3/urllib3/util/connection.py", line 60, in create_connection
    for res in socket.getaddrinfo(host, port, family, socket.SOCK_STREAM):
  File "/Library/Frameworks/Python.framework/Versions/3.7/lib/python3.7/socket.py", line 748, in getaddrinfo
    for res in _socket.getaddrinfo(host, port, family, type, proto, flags):
socket.gaierror: [Errno 8] nodename nor servname provided, or not known

During handling of the above exception, another exception occurred:

Traceback (most recent call last):
  File "/Library/Frameworks/Python.framework/Versions/3.7/lib/python3.7/site-packages/telegram/vendor/ptb_urllib3/urllib3/connectionpool.py", line 617, in urlopen
    chunked=chunked)
  File "/Library/Frameworks/Python.framework/Versions/3.7/lib/python3.7/site-packages/telegram/vendor/ptb_urllib3/urllib3/connectionpool.py", line 360, in _make_request
    self._validate_conn(conn)
  File "/Library/Frameworks/Python.framework/Versions/3.7/lib/python3.7/site-packages/telegram/vendor/ptb_urllib3/urllib3/connectionpool.py", line 857, in _validate_conn
    super(HTTPSConnectionPool, self)._validate_conn(conn)
  File "/Library/Frameworks/Python.framework/Versions/3.7/lib/python3.7/site-packages/telegram/vendor/ptb_urllib3/urllib3/connectionpool.py", line 289, in _validate_conn
    conn.connect()
  File "/Library/Frameworks/Python.framework/Versions/3.7/lib/python3.7/site-packages/telegram/vendor/ptb_urllib3/urllib3/connection.py", line 284, in connect
    conn = self._new_conn()
  File "/Library/Frameworks/Python.framework/Versions/3.7/lib/python3.7/site-packages/telegram/vendor/ptb_urllib3/urllib3/connection.py", line 150, in _new_conn
    self, "Failed to establish a new connection: %s" % e)
telegram.vendor.ptb_urllib3.urllib3.exceptions.NewConnectionError: <telegram.vendor.ptb_urllib3.urllib3.connection.VerifiedHTTPSConnection object at 0x1109011d0>: Failed to establish a new connection: [Errno 8] nodename nor servname provided, or not known

During handling of the above exception, another exception occurred:

Traceback (most recent call last):
  File "/Library/Frameworks/Python.framework/Versions/3.7/lib/python3.7/site-packages/telegram/utils/request.py", line 218, in _request_wrapper
    resp = self._con_pool.request(*args, **kwargs)
  File "/Library/Frameworks/Python.framework/Versions/3.7/lib/python3.7/site-packages/telegram/vendor/ptb_urllib3/urllib3/request.py", line 70, in request
    **urlopen_kw)
  File "/Library/Frameworks/Python.framework/Versions/3.7/lib/python3.7/site-packages/telegram/vendor/ptb_urllib3/urllib3/request.py", line 148, in request_encode_body
    return self.urlopen(method, url, **extra_kw)
  File "/Library/Frameworks/Python.framework/Versions/3.7/lib/python3.7/site-packages/telegram/vendor/ptb_urllib3/urllib3/poolmanager.py", line 244, in urlopen
    response = conn.urlopen(method, u.request_uri, **kw)
  File "/Library/Frameworks/Python.framework/Versions/3.7/lib/python3.7/site-packages/telegram/vendor/ptb_urllib3/urllib3/connectionpool.py", line 695, in urlopen
    **response_kw)
  File "/Library/Frameworks/Python.framework/Versions/3.7/lib/python3.7/site-packages/telegram/vendor/ptb_urllib3/urllib3/connectionpool.py", line 695, in urlopen
    **response_kw)
  File "/Library/Frameworks/Python.framework/Versions/3.7/lib/python3.7/site-packages/telegram/vendor/ptb_urllib3/urllib3/connectionpool.py", line 695, in urlopen
    **response_kw)
  File "/Library/Frameworks/Python.framework/Versions/3.7/lib/python3.7/site-packages/telegram/vendor/ptb_urllib3/urllib3/connectionpool.py", line 666, in urlopen
    _stacktrace=sys.exc_info()[2])
  File "/Library/Frameworks/Python.framework/Versions/3.7/lib/python3.7/site-packages/telegram/vendor/ptb_urllib3/urllib3/util/retry.py", line 376, in increment
    raise MaxRetryError(_pool, url, error or ResponseError(cause))
telegram.vendor.ptb_urllib3.urllib3.exceptions.MaxRetryError: HTTPSConnectionPool(host='api.telegram.org', port=443): Max retries exceeded with url: /bot808049629:AAHXH6XLn_2HpMGsgUBn9y0TCI2mn22mJ8A/getUpdates (Caused by NewConnectionError('<telegram.vendor.ptb_urllib3.urllib3.connection.VerifiedHTTPSConnection object at 0x1109011d0>: Failed to establish a new connection: [Errno 8] nodename nor servname provided, or not known'))

During handling of the above exception, another exception occurred:

Traceback (most recent call last):
  File "/Library/Frameworks/Python.framework/Versions/3.7/lib/python3.7/site-packages/telegram/ext/updater.py", line 332, in _network_loop_retry
    if not action_cb():
  File "/Library/Frameworks/Python.framework/Versions/3.7/lib/python3.7/site-packages/telegram/ext/updater.py", line 293, in polling_action_cb
    allowed_updates=allowed_updates)
  File "/Library/Frameworks/Python.framework/Versions/3.7/lib/python3.7/site-packages/telegram/bot.py", line 66, in decorator
    result = func(self, *args, **kwargs)
  File "/Library/Frameworks/Python.framework/Versions/3.7/lib/python3.7/site-packages/telegram/bot.py", line 1982, in get_updates
    result = self._request.post(url, data, timeout=float(read_latency) + float(timeout))
  File "/Library/Frameworks/Python.framework/Versions/3.7/lib/python3.7/site-packages/telegram/utils/request.py", line 327, in post
    **urlopen_kwargs)
  File "/Library/Frameworks/Python.framework/Versions/3.7/lib/python3.7/site-packages/telegram/utils/request.py", line 224, in _request_wrapper
    raise NetworkError('urllib3 HTTPError {0}'.format(error))
telegram.error.NetworkError: urllib3 HTTPError HTTPSConnectionPool(host='api.telegram.org', port=443): Max retries exceeded with url: /bot808049629:AAHXH6XLn_2HpMGsgUBn9y0TCI2mn22mJ8A/getUpdates (Caused by NewConnectionError('<telegram.vendor.ptb_urllib3.urllib3.connection.VerifiedHTTPSConnection object at 0x1109011d0>: Failed to establish a new connection: [Errno 8] nodename nor servname provided, or not known'))
telegram.vendor.ptb_urllib3.urllib3.connectionpool - WARNING - Retrying (Retry(total=2, connect=None, read=None, redirect=None)) after connection broken by 'NewConnectionError('<telegram.vendor.ptb_urllib3.urllib3.connection.VerifiedHTTPSConnection object at 0x1109012d0>: Failed to establish a new connection: [Errno 8] nodename nor servname provided, or not known')': /bot808049629:AAHXH6XLn_2HpMGsgUBn9y0TCI2mn22mJ8A/getUpdates
telegram.vendor.ptb_urllib3.urllib3.connectionpool - WARNING - Retrying (Retry(total=1, connect=None, read=None, redirect=None)) after connection broken by 'NewConnectionError('<telegram.vendor.ptb_urllib3.urllib3.connection.VerifiedHTTPSConnection object at 0x1109015d0>: Failed to establish a new connection: [Errno 8] nodename nor servname provided, or not known')': /bot808049629:AAHXH6XLn_2HpMGsgUBn9y0TCI2mn22mJ8A/getUpdates
telegram.vendor.ptb_urllib3.urllib3.connectionpool - WARNING - Retrying (Retry(total=0, connect=None, read=None, redirect=None)) after connection broken by 'NewConnectionError('<telegram.vendor.ptb_urllib3.urllib3.connection.VerifiedHTTPSConnection object at 0x110901d10>: Failed to establish a new connection: [Errno 8] nodename nor servname provided, or not known')': /bot808049629:AAHXH6XLn_2HpMGsgUBn9y0TCI2mn22mJ8A/getUpdates
telegram.ext.updater - ERROR - Error while getting Updates: urllib3 HTTPError HTTPSConnectionPool(host='api.telegram.org', port=443): Max retries exceeded with url: /bot808049629:AAHXH6XLn_2HpMGsgUBn9y0TCI2mn22mJ8A/getUpdates (Caused by NewConnectionError('<telegram.vendor.ptb_urllib3.urllib3.connection.VerifiedHTTPSConnection object at 0x110a16150>: Failed to establish a new connection: [Errno 8] nodename nor servname provided, or not known'))
telegram.ext.dispatcher - ERROR - No error handlers are registered, logging exception.
Traceback (most recent call last):
  File "/Library/Frameworks/Python.framework/Versions/3.7/lib/python3.7/site-packages/telegram/vendor/ptb_urllib3/urllib3/connection.py", line 141, in _new_conn
    (self.host, self.port), self.timeout, **extra_kw)
  File "/Library/Frameworks/Python.framework/Versions/3.7/lib/python3.7/site-packages/telegram/vendor/ptb_urllib3/urllib3/util/connection.py", line 60, in create_connection
    for res in socket.getaddrinfo(host, port, family, socket.SOCK_STREAM):
  File "/Library/Frameworks/Python.framework/Versions/3.7/lib/python3.7/socket.py", line 748, in getaddrinfo
    for res in _socket.getaddrinfo(host, port, family, type, proto, flags):
socket.gaierror: [Errno 8] nodename nor servname provided, or not known

During handling of the above exception, another exception occurred:

Traceback (most recent call last):
  File "/Library/Frameworks/Python.framework/Versions/3.7/lib/python3.7/site-packages/telegram/vendor/ptb_urllib3/urllib3/connectionpool.py", line 617, in urlopen
    chunked=chunked)
  File "/Library/Frameworks/Python.framework/Versions/3.7/lib/python3.7/site-packages/telegram/vendor/ptb_urllib3/urllib3/connectionpool.py", line 360, in _make_request
    self._validate_conn(conn)
  File "/Library/Frameworks/Python.framework/Versions/3.7/lib/python3.7/site-packages/telegram/vendor/ptb_urllib3/urllib3/connectionpool.py", line 857, in _validate_conn
    super(HTTPSConnectionPool, self)._validate_conn(conn)
  File "/Library/Frameworks/Python.framework/Versions/3.7/lib/python3.7/site-packages/telegram/vendor/ptb_urllib3/urllib3/connectionpool.py", line 289, in _validate_conn
    conn.connect()
  File "/Library/Frameworks/Python.framework/Versions/3.7/lib/python3.7/site-packages/telegram/vendor/ptb_urllib3/urllib3/connection.py", line 284, in connect
    conn = self._new_conn()
  File "/Library/Frameworks/Python.framework/Versions/3.7/lib/python3.7/site-packages/telegram/vendor/ptb_urllib3/urllib3/connection.py", line 150, in _new_conn
    self, "Failed to establish a new connection: %s" % e)
telegram.vendor.ptb_urllib3.urllib3.exceptions.NewConnectionError: <telegram.vendor.ptb_urllib3.urllib3.connection.VerifiedHTTPSConnection object at 0x110a16150>: Failed to establish a new connection: [Errno 8] nodename nor servname provided, or not known

During handling of the above exception, another exception occurred:

Traceback (most recent call last):
  File "/Library/Frameworks/Python.framework/Versions/3.7/lib/python3.7/site-packages/telegram/utils/request.py", line 218, in _request_wrapper
    resp = self._con_pool.request(*args, **kwargs)
  File "/Library/Frameworks/Python.framework/Versions/3.7/lib/python3.7/site-packages/telegram/vendor/ptb_urllib3/urllib3/request.py", line 70, in request
    **urlopen_kw)
  File "/Library/Frameworks/Python.framework/Versions/3.7/lib/python3.7/site-packages/telegram/vendor/ptb_urllib3/urllib3/request.py", line 148, in request_encode_body
    return self.urlopen(method, url, **extra_kw)
  File "/Library/Frameworks/Python.framework/Versions/3.7/lib/python3.7/site-packages/telegram/vendor/ptb_urllib3/urllib3/poolmanager.py", line 244, in urlopen
    response = conn.urlopen(method, u.request_uri, **kw)
  File "/Library/Frameworks/Python.framework/Versions/3.7/lib/python3.7/site-packages/telegram/vendor/ptb_urllib3/urllib3/connectionpool.py", line 695, in urlopen
    **response_kw)
  File "/Library/Frameworks/Python.framework/Versions/3.7/lib/python3.7/site-packages/telegram/vendor/ptb_urllib3/urllib3/connectionpool.py", line 695, in urlopen
    **response_kw)
  File "/Library/Frameworks/Python.framework/Versions/3.7/lib/python3.7/site-packages/telegram/vendor/ptb_urllib3/urllib3/connectionpool.py", line 695, in urlopen
    **response_kw)
  File "/Library/Frameworks/Python.framework/Versions/3.7/lib/python3.7/site-packages/telegram/vendor/ptb_urllib3/urllib3/connectionpool.py", line 666, in urlopen
    _stacktrace=sys.exc_info()[2])
  File "/Library/Frameworks/Python.framework/Versions/3.7/lib/python3.7/site-packages/telegram/vendor/ptb_urllib3/urllib3/util/retry.py", line 376, in increment
    raise MaxRetryError(_pool, url, error or ResponseError(cause))
telegram.vendor.ptb_urllib3.urllib3.exceptions.MaxRetryError: HTTPSConnectionPool(host='api.telegram.org', port=443): Max retries exceeded with url: /bot808049629:AAHXH6XLn_2HpMGsgUBn9y0TCI2mn22mJ8A/getUpdates (Caused by NewConnectionError('<telegram.vendor.ptb_urllib3.urllib3.connection.VerifiedHTTPSConnection object at 0x110a16150>: Failed to establish a new connection: [Errno 8] nodename nor servname provided, or not known'))

During handling of the above exception, another exception occurred:

Traceback (most recent call last):
  File "/Library/Frameworks/Python.framework/Versions/3.7/lib/python3.7/site-packages/telegram/ext/updater.py", line 332, in _network_loop_retry
    if not action_cb():
  File "/Library/Frameworks/Python.framework/Versions/3.7/lib/python3.7/site-packages/telegram/ext/updater.py", line 293, in polling_action_cb
    allowed_updates=allowed_updates)
  File "/Library/Frameworks/Python.framework/Versions/3.7/lib/python3.7/site-packages/telegram/bot.py", line 66, in decorator
    result = func(self, *args, **kwargs)
  File "/Library/Frameworks/Python.framework/Versions/3.7/lib/python3.7/site-packages/telegram/bot.py", line 1982, in get_updates
    result = self._request.post(url, data, timeout=float(read_latency) + float(timeout))
  File "/Library/Frameworks/Python.framework/Versions/3.7/lib/python3.7/site-packages/telegram/utils/request.py", line 327, in post
    **urlopen_kwargs)
  File "/Library/Frameworks/Python.framework/Versions/3.7/lib/python3.7/site-packages/telegram/utils/request.py", line 224, in _request_wrapper
    raise NetworkError('urllib3 HTTPError {0}'.format(error))
telegram.error.NetworkError: urllib3 HTTPError HTTPSConnectionPool(host='api.telegram.org', port=443): Max retries exceeded with url: /bot808049629:AAHXH6XLn_2HpMGsgUBn9y0TCI2mn22mJ8A/getUpdates (Caused by NewConnectionError('<telegram.vendor.ptb_urllib3.urllib3.connection.VerifiedHTTPSConnection object at 0x110a16150>: Failed to establish a new connection: [Errno 8] nodename nor servname provided, or not known'))
telegram.vendor.ptb_urllib3.urllib3.connectionpool - WARNING - Retrying (Retry(total=2, connect=None, read=None, redirect=None)) after connection broken by 'NewConnectionError('<telegram.vendor.ptb_urllib3.urllib3.connection.VerifiedHTTPSConnection object at 0x110901650>: Failed to establish a new connection: [Errno 8] nodename nor servname provided, or not known')': /bot808049629:AAHXH6XLn_2HpMGsgUBn9y0TCI2mn22mJ8A/getUpdates
telegram.vendor.ptb_urllib3.urllib3.connectionpool - WARNING - Retrying (Retry(total=1, connect=None, read=None, redirect=None)) after connection broken by 'NewConnectionError('<telegram.vendor.ptb_urllib3.urllib3.connection.VerifiedHTTPSConnection object at 0x110a16190>: Failed to establish a new connection: [Errno 8] nodename nor servname provided, or not known')': /bot808049629:AAHXH6XLn_2HpMGsgUBn9y0TCI2mn22mJ8A/getUpdates
telegram.vendor.ptb_urllib3.urllib3.connectionpool - WARNING - Retrying (Retry(total=0, connect=None, read=None, redirect=None)) after connection broken by 'NewConnectionError('<telegram.vendor.ptb_urllib3.urllib3.connection.VerifiedHTTPSConnection object at 0x110a16450>: Failed to establish a new connection: [Errno 8] nodename nor servname provided, or not known')': /bot808049629:AAHXH6XLn_2HpMGsgUBn9y0TCI2mn22mJ8A/getUpdates
telegram.ext.updater - ERROR - Error while getting Updates: urllib3 HTTPError HTTPSConnectionPool(host='api.telegram.org', port=443): Max retries exceeded with url: /bot808049629:AAHXH6XLn_2HpMGsgUBn9y0TCI2mn22mJ8A/getUpdates (Caused by NewConnectionError('<telegram.vendor.ptb_urllib3.urllib3.connection.VerifiedHTTPSConnection object at 0x110a16610>: Failed to establish a new connection: [Errno 8] nodename nor servname provided, or not known'))
telegram.ext.dispatcher - ERROR - No error handlers are registered, logging exception.
Traceback (most recent call last):
  File "/Library/Frameworks/Python.framework/Versions/3.7/lib/python3.7/site-packages/telegram/vendor/ptb_urllib3/urllib3/connection.py", line 141, in _new_conn
    (self.host, self.port), self.timeout, **extra_kw)
  File "/Library/Frameworks/Python.framework/Versions/3.7/lib/python3.7/site-packages/telegram/vendor/ptb_urllib3/urllib3/util/connection.py", line 60, in create_connection
    for res in socket.getaddrinfo(host, port, family, socket.SOCK_STREAM):
  File "/Library/Frameworks/Python.framework/Versions/3.7/lib/python3.7/socket.py", line 748, in getaddrinfo
    for res in _socket.getaddrinfo(host, port, family, type, proto, flags):
socket.gaierror: [Errno 8] nodename nor servname provided, or not known

During handling of the above exception, another exception occurred:

Traceback (most recent call last):
  File "/Library/Frameworks/Python.framework/Versions/3.7/lib/python3.7/site-packages/telegram/vendor/ptb_urllib3/urllib3/connectionpool.py", line 617, in urlopen
    chunked=chunked)
  File "/Library/Frameworks/Python.framework/Versions/3.7/lib/python3.7/site-packages/telegram/vendor/ptb_urllib3/urllib3/connectionpool.py", line 360, in _make_request
    self._validate_conn(conn)
  File "/Library/Frameworks/Python.framework/Versions/3.7/lib/python3.7/site-packages/telegram/vendor/ptb_urllib3/urllib3/connectionpool.py", line 857, in _validate_conn
    super(HTTPSConnectionPool, self)._validate_conn(conn)
  File "/Library/Frameworks/Python.framework/Versions/3.7/lib/python3.7/site-packages/telegram/vendor/ptb_urllib3/urllib3/connectionpool.py", line 289, in _validate_conn
    conn.connect()
  File "/Library/Frameworks/Python.framework/Versions/3.7/lib/python3.7/site-packages/telegram/vendor/ptb_urllib3/urllib3/connection.py", line 284, in connect
    conn = self._new_conn()
  File "/Library/Frameworks/Python.framework/Versions/3.7/lib/python3.7/site-packages/telegram/vendor/ptb_urllib3/urllib3/connection.py", line 150, in _new_conn
    self, "Failed to establish a new connection: %s" % e)
telegram.vendor.ptb_urllib3.urllib3.exceptions.NewConnectionError: <telegram.vendor.ptb_urllib3.urllib3.connection.VerifiedHTTPSConnection object at 0x110a16610>: Failed to establish a new connection: [Errno 8] nodename nor servname provided, or not known

During handling of the above exception, another exception occurred:

Traceback (most recent call last):
  File "/Library/Frameworks/Python.framework/Versions/3.7/lib/python3.7/site-packages/telegram/utils/request.py", line 218, in _request_wrapper
    resp = self._con_pool.request(*args, **kwargs)
  File "/Library/Frameworks/Python.framework/Versions/3.7/lib/python3.7/site-packages/telegram/vendor/ptb_urllib3/urllib3/request.py", line 70, in request
    **urlopen_kw)
  File "/Library/Frameworks/Python.framework/Versions/3.7/lib/python3.7/site-packages/telegram/vendor/ptb_urllib3/urllib3/request.py", line 148, in request_encode_body
    return self.urlopen(method, url, **extra_kw)
  File "/Library/Frameworks/Python.framework/Versions/3.7/lib/python3.7/site-packages/telegram/vendor/ptb_urllib3/urllib3/poolmanager.py", line 244, in urlopen
    response = conn.urlopen(method, u.request_uri, **kw)
  File "/Library/Frameworks/Python.framework/Versions/3.7/lib/python3.7/site-packages/telegram/vendor/ptb_urllib3/urllib3/connectionpool.py", line 695, in urlopen
    **response_kw)
  File "/Library/Frameworks/Python.framework/Versions/3.7/lib/python3.7/site-packages/telegram/vendor/ptb_urllib3/urllib3/connectionpool.py", line 695, in urlopen
    **response_kw)
  File "/Library/Frameworks/Python.framework/Versions/3.7/lib/python3.7/site-packages/telegram/vendor/ptb_urllib3/urllib3/connectionpool.py", line 695, in urlopen
    **response_kw)
  File "/Library/Frameworks/Python.framework/Versions/3.7/lib/python3.7/site-packages/telegram/vendor/ptb_urllib3/urllib3/connectionpool.py", line 666, in urlopen
    _stacktrace=sys.exc_info()[2])
  File "/Library/Frameworks/Python.framework/Versions/3.7/lib/python3.7/site-packages/telegram/vendor/ptb_urllib3/urllib3/util/retry.py", line 376, in increment
    raise MaxRetryError(_pool, url, error or ResponseError(cause))
telegram.vendor.ptb_urllib3.urllib3.exceptions.MaxRetryError: HTTPSConnectionPool(host='api.telegram.org', port=443): Max retries exceeded with url: /bot808049629:AAHXH6XLn_2HpMGsgUBn9y0TCI2mn22mJ8A/getUpdates (Caused by NewConnectionError('<telegram.vendor.ptb_urllib3.urllib3.connection.VerifiedHTTPSConnection object at 0x110a16610>: Failed to establish a new connection: [Errno 8] nodename nor servname provided, or not known'))

During handling of the above exception, another exception occurred:

Traceback (most recent call last):
  File "/Library/Frameworks/Python.framework/Versions/3.7/lib/python3.7/site-packages/telegram/ext/updater.py", line 332, in _network_loop_retry
    if not action_cb():
  File "/Library/Frameworks/Python.framework/Versions/3.7/lib/python3.7/site-packages/telegram/ext/updater.py", line 293, in polling_action_cb
    allowed_updates=allowed_updates)
  File "/Library/Frameworks/Python.framework/Versions/3.7/lib/python3.7/site-packages/telegram/bot.py", line 66, in decorator
    result = func(self, *args, **kwargs)
  File "/Library/Frameworks/Python.framework/Versions/3.7/lib/python3.7/site-packages/telegram/bot.py", line 1982, in get_updates
    result = self._request.post(url, data, timeout=float(read_latency) + float(timeout))
  File "/Library/Frameworks/Python.framework/Versions/3.7/lib/python3.7/site-packages/telegram/utils/request.py", line 327, in post
    **urlopen_kwargs)
  File "/Library/Frameworks/Python.framework/Versions/3.7/lib/python3.7/site-packages/telegram/utils/request.py", line 224, in _request_wrapper
    raise NetworkError('urllib3 HTTPError {0}'.format(error))
telegram.error.NetworkError: urllib3 HTTPError HTTPSConnectionPool(host='api.telegram.org', port=443): Max retries exceeded with url: /bot808049629:AAHXH6XLn_2HpMGsgUBn9y0TCI2mn22mJ8A/getUpdates (Caused by NewConnectionError('<telegram.vendor.ptb_urllib3.urllib3.connection.VerifiedHTTPSConnection object at 0x110a16610>: Failed to establish a new connection: [Errno 8] nodename nor servname provided, or not known'))
telegram.vendor.ptb_urllib3.urllib3.connectionpool - WARNING - Retrying (Retry(total=2, connect=None, read=None, redirect=None)) after connection broken by 'NewConnectionError('<telegram.vendor.ptb_urllib3.urllib3.connection.VerifiedHTTPSConnection object at 0x110a16290>: Failed to establish a new connection: [Errno 8] nodename nor servname provided, or not known')': /bot808049629:AAHXH6XLn_2HpMGsgUBn9y0TCI2mn22mJ8A/getUpdates
telegram.vendor.ptb_urllib3.urllib3.connectionpool - WARNING - Retrying (Retry(total=1, connect=None, read=None, redirect=None)) after connection broken by 'NewConnectionError('<telegram.vendor.ptb_urllib3.urllib3.connection.VerifiedHTTPSConnection object at 0x110a167d0>: Failed to establish a new connection: [Errno 8] nodename nor servname provided, or not known')': /bot808049629:AAHXH6XLn_2HpMGsgUBn9y0TCI2mn22mJ8A/getUpdates
telegram.vendor.ptb_urllib3.urllib3.connectionpool - WARNING - Retrying (Retry(total=0, connect=None, read=None, redirect=None)) after connection broken by 'NewConnectionError('<telegram.vendor.ptb_urllib3.urllib3.connection.VerifiedHTTPSConnection object at 0x110a16a50>: Failed to establish a new connection: [Errno 8] nodename nor servname provided, or not known')': /bot808049629:AAHXH6XLn_2HpMGsgUBn9y0TCI2mn22mJ8A/getUpdates
telegram.ext.updater - ERROR - Error while getting Updates: urllib3 HTTPError HTTPSConnectionPool(host='api.telegram.org', port=443): Max retries exceeded with url: /bot808049629:AAHXH6XLn_2HpMGsgUBn9y0TCI2mn22mJ8A/getUpdates (Caused by NewConnectionError('<telegram.vendor.ptb_urllib3.urllib3.connection.VerifiedHTTPSConnection object at 0x110a16bd0>: Failed to establish a new connection: [Errno 8] nodename nor servname provided, or not known'))
telegram.ext.dispatcher - ERROR - No error handlers are registered, logging exception.
Traceback (most recent call last):
  File "/Library/Frameworks/Python.framework/Versions/3.7/lib/python3.7/site-packages/telegram/vendor/ptb_urllib3/urllib3/connection.py", line 141, in _new_conn
    (self.host, self.port), self.timeout, **extra_kw)
  File "/Library/Frameworks/Python.framework/Versions/3.7/lib/python3.7/site-packages/telegram/vendor/ptb_urllib3/urllib3/util/connection.py", line 60, in create_connection
    for res in socket.getaddrinfo(host, port, family, socket.SOCK_STREAM):
  File "/Library/Frameworks/Python.framework/Versions/3.7/lib/python3.7/socket.py", line 748, in getaddrinfo
    for res in _socket.getaddrinfo(host, port, family, type, proto, flags):
socket.gaierror: [Errno 8] nodename nor servname provided, or not known

During handling of the above exception, another exception occurred:

Traceback (most recent call last):
  File "/Library/Frameworks/Python.framework/Versions/3.7/lib/python3.7/site-packages/telegram/vendor/ptb_urllib3/urllib3/connectionpool.py", line 617, in urlopen
    chunked=chunked)
  File "/Library/Frameworks/Python.framework/Versions/3.7/lib/python3.7/site-packages/telegram/vendor/ptb_urllib3/urllib3/connectionpool.py", line 360, in _make_request
    self._validate_conn(conn)
  File "/Library/Frameworks/Python.framework/Versions/3.7/lib/python3.7/site-packages/telegram/vendor/ptb_urllib3/urllib3/connectionpool.py", line 857, in _validate_conn
    super(HTTPSConnectionPool, self)._validate_conn(conn)
  File "/Library/Frameworks/Python.framework/Versions/3.7/lib/python3.7/site-packages/telegram/vendor/ptb_urllib3/urllib3/connectionpool.py", line 289, in _validate_conn
    conn.connect()
  File "/Library/Frameworks/Python.framework/Versions/3.7/lib/python3.7/site-packages/telegram/vendor/ptb_urllib3/urllib3/connection.py", line 284, in connect
    conn = self._new_conn()
  File "/Library/Frameworks/Python.framework/Versions/3.7/lib/python3.7/site-packages/telegram/vendor/ptb_urllib3/urllib3/connection.py", line 150, in _new_conn
    self, "Failed to establish a new connection: %s" % e)
telegram.vendor.ptb_urllib3.urllib3.exceptions.NewConnectionError: <telegram.vendor.ptb_urllib3.urllib3.connection.VerifiedHTTPSConnection object at 0x110a16bd0>: Failed to establish a new connection: [Errno 8] nodename nor servname provided, or not known

During handling of the above exception, another exception occurred:

Traceback (most recent call last):
  File "/Library/Frameworks/Python.framework/Versions/3.7/lib/python3.7/site-packages/telegram/utils/request.py", line 218, in _request_wrapper
    resp = self._con_pool.request(*args, **kwargs)
  File "/Library/Frameworks/Python.framework/Versions/3.7/lib/python3.7/site-packages/telegram/vendor/ptb_urllib3/urllib3/request.py", line 70, in request
    **urlopen_kw)
  File "/Library/Frameworks/Python.framework/Versions/3.7/lib/python3.7/site-packages/telegram/vendor/ptb_urllib3/urllib3/request.py", line 148, in request_encode_body
    return self.urlopen(method, url, **extra_kw)
  File "/Library/Frameworks/Python.framework/Versions/3.7/lib/python3.7/site-packages/telegram/vendor/ptb_urllib3/urllib3/poolmanager.py", line 244, in urlopen
    response = conn.urlopen(method, u.request_uri, **kw)
  File "/Library/Frameworks/Python.framework/Versions/3.7/lib/python3.7/site-packages/telegram/vendor/ptb_urllib3/urllib3/connectionpool.py", line 695, in urlopen
    **response_kw)
  File "/Library/Frameworks/Python.framework/Versions/3.7/lib/python3.7/site-packages/telegram/vendor/ptb_urllib3/urllib3/connectionpool.py", line 695, in urlopen
    **response_kw)
  File "/Library/Frameworks/Python.framework/Versions/3.7/lib/python3.7/site-packages/telegram/vendor/ptb_urllib3/urllib3/connectionpool.py", line 695, in urlopen
    **response_kw)
  File "/Library/Frameworks/Python.framework/Versions/3.7/lib/python3.7/site-packages/telegram/vendor/ptb_urllib3/urllib3/connectionpool.py", line 666, in urlopen
    _stacktrace=sys.exc_info()[2])
  File "/Library/Frameworks/Python.framework/Versions/3.7/lib/python3.7/site-packages/telegram/vendor/ptb_urllib3/urllib3/util/retry.py", line 376, in increment
    raise MaxRetryError(_pool, url, error or ResponseError(cause))
telegram.vendor.ptb_urllib3.urllib3.exceptions.MaxRetryError: HTTPSConnectionPool(host='api.telegram.org', port=443): Max retries exceeded with url: /bot808049629:AAHXH6XLn_2HpMGsgUBn9y0TCI2mn22mJ8A/getUpdates (Caused by NewConnectionError('<telegram.vendor.ptb_urllib3.urllib3.connection.VerifiedHTTPSConnection object at 0x110a16bd0>: Failed to establish a new connection: [Errno 8] nodename nor servname provided, or not known'))

During handling of the above exception, another exception occurred:

Traceback (most recent call last):
  File "/Library/Frameworks/Python.framework/Versions/3.7/lib/python3.7/site-packages/telegram/ext/updater.py", line 332, in _network_loop_retry
    if not action_cb():
  File "/Library/Frameworks/Python.framework/Versions/3.7/lib/python3.7/site-packages/telegram/ext/updater.py", line 293, in polling_action_cb
    allowed_updates=allowed_updates)
  File "/Library/Frameworks/Python.framework/Versions/3.7/lib/python3.7/site-packages/telegram/bot.py", line 66, in decorator
    result = func(self, *args, **kwargs)
  File "/Library/Frameworks/Python.framework/Versions/3.7/lib/python3.7/site-packages/telegram/bot.py", line 1982, in get_updates
    result = self._request.post(url, data, timeout=float(read_latency) + float(timeout))
  File "/Library/Frameworks/Python.framework/Versions/3.7/lib/python3.7/site-packages/telegram/utils/request.py", line 327, in post
    **urlopen_kwargs)
  File "/Library/Frameworks/Python.framework/Versions/3.7/lib/python3.7/site-packages/telegram/utils/request.py", line 224, in _request_wrapper
    raise NetworkError('urllib3 HTTPError {0}'.format(error))
telegram.error.NetworkError: urllib3 HTTPError HTTPSConnectionPool(host='api.telegram.org', port=443): Max retries exceeded with url: /bot808049629:AAHXH6XLn_2HpMGsgUBn9y0TCI2mn22mJ8A/getUpdates (Caused by NewConnectionError('<telegram.vendor.ptb_urllib3.urllib3.connection.VerifiedHTTPSConnection object at 0x110a16bd0>: Failed to establish a new connection: [Errno 8] nodename nor servname provided, or not known'))
telegram.vendor.ptb_urllib3.urllib3.connectionpool - WARNING - Retrying (Retry(total=2, connect=None, read=None, redirect=None)) after connection broken by 'ConnectTimeoutError(<telegram.vendor.ptb_urllib3.urllib3.connection.VerifiedHTTPSConnection object at 0x110a16dd0>, 'Connection to api.telegram.org timed out. (connect timeout=5.0)')': /bot808049629:AAHXH6XLn_2HpMGsgUBn9y0TCI2mn22mJ8A/getUpdates
telegram.vendor.ptb_urllib3.urllib3.connectionpool - WARNING - Retrying (Retry(total=1, connect=None, read=None, redirect=None)) after connection broken by 'ConnectTimeoutError(<telegram.vendor.ptb_urllib3.urllib3.connection.VerifiedHTTPSConnection object at 0x110a16d50>, 'Connection to api.telegram.org timed out. (connect timeout=5.0)')': /bot808049629:AAHXH6XLn_2HpMGsgUBn9y0TCI2mn22mJ8A/getUpdates
telegram.vendor.ptb_urllib3.urllib3.connectionpool - WARNING - Retrying (Retry(total=0, connect=None, read=None, redirect=None)) after connection broken by 'ConnectTimeoutError(<telegram.vendor.ptb_urllib3.urllib3.connection.VerifiedHTTPSConnection object at 0x110901650>, 'Connection to api.telegram.org timed out. (connect timeout=5.0)')': /bot808049629:AAHXH6XLn_2HpMGsgUBn9y0TCI2mn22mJ8A/getUpdates
